{
  "nbformat": 4,
  "nbformat_minor": 0,
  "metadata": {
    "colab": {
      "provenance": []
    },
    "kernelspec": {
      "name": "python3",
      "display_name": "Python 3"
    },
    "language_info": {
      "name": "python"
    }
  },
  "cells": [
    {
      "cell_type": "code",
      "source": [
        "# prompt: ModuleNotFoundError: No module named 'keras.preprocessing.text'\n",
        "!pip install keras --upgrade\n",
        "# now you can use keras.preprocessing.text\n"
      ],
      "metadata": {
        "colab": {
          "base_uri": "https://localhost:8080/"
        },
        "id": "oxLvNTcMPky9",
        "outputId": "a36e5fff-ce98-42f5-e4e8-efae1e579200"
      },
      "execution_count": 21,
      "outputs": [
        {
          "output_type": "stream",
          "name": "stdout",
          "text": [
            "Requirement already satisfied: keras in /usr/local/lib/python3.11/dist-packages (3.9.2)\n",
            "Requirement already satisfied: absl-py in /usr/local/lib/python3.11/dist-packages (from keras) (1.4.0)\n",
            "Requirement already satisfied: numpy in /usr/local/lib/python3.11/dist-packages (from keras) (2.0.2)\n",
            "Requirement already satisfied: rich in /usr/local/lib/python3.11/dist-packages (from keras) (13.9.4)\n",
            "Requirement already satisfied: namex in /usr/local/lib/python3.11/dist-packages (from keras) (0.0.9)\n",
            "Requirement already satisfied: h5py in /usr/local/lib/python3.11/dist-packages (from keras) (3.13.0)\n",
            "Requirement already satisfied: optree in /usr/local/lib/python3.11/dist-packages (from keras) (0.15.0)\n",
            "Requirement already satisfied: ml-dtypes in /usr/local/lib/python3.11/dist-packages (from keras) (0.4.1)\n",
            "Requirement already satisfied: packaging in /usr/local/lib/python3.11/dist-packages (from keras) (24.2)\n",
            "Requirement already satisfied: typing-extensions>=4.5.0 in /usr/local/lib/python3.11/dist-packages (from optree->keras) (4.13.2)\n",
            "Requirement already satisfied: markdown-it-py>=2.2.0 in /usr/local/lib/python3.11/dist-packages (from rich->keras) (3.0.0)\n",
            "Requirement already satisfied: pygments<3.0.0,>=2.13.0 in /usr/local/lib/python3.11/dist-packages (from rich->keras) (2.19.1)\n",
            "Requirement already satisfied: mdurl~=0.1 in /usr/local/lib/python3.11/dist-packages (from markdown-it-py>=2.2.0->rich->keras) (0.1.2)\n"
          ]
        }
      ]
    },
    {
      "cell_type": "code",
      "execution_count": 22,
      "metadata": {
        "colab": {
          "base_uri": "https://localhost:8080/"
        },
        "id": "28U97kmDOJmw",
        "outputId": "9550345f-df02-4393-b643-fc91b6f3fece"
      },
      "outputs": [
        {
          "output_type": "stream",
          "name": "stderr",
          "text": [
            "<ipython-input-22-23daeded08de>:24: FutureWarning: Series.__getitem__ treating keys as positions is deprecated. In a future version, integer keys will always be treated as labels (consistent with DataFrame behavior). To access a value by position, use `ser.iloc[pos]`\n",
            "  row[0] = row[0].replace('rt', ' ')\n",
            "<ipython-input-22-23daeded08de>:24: FutureWarning: Series.__setitem__ treating keys as positions is deprecated. In a future version, integer keys will always be treated as labels (consistent with DataFrame behavior). To set a value by position, use `ser.iloc[pos] = value`\n",
            "  row[0] = row[0].replace('rt', ' ')\n",
            "/usr/local/lib/python3.11/dist-packages/keras/src/layers/core/embedding.py:90: UserWarning: Argument `input_length` is deprecated. Just remove it.\n",
            "  warnings.warn(\n"
          ]
        },
        {
          "output_type": "stream",
          "name": "stdout",
          "text": [
            "291/291 - 53s - 183ms/step - accuracy: 0.6404 - loss: 0.8346\n",
            "144/144 - 4s - 30ms/step - accuracy: 0.6693 - loss: 0.7561\n",
            "0.7560551166534424\n",
            "0.669287919998169\n",
            "['loss', 'compile_metrics']\n"
          ]
        }
      ],
      "source": [
        "import pandas as pd # data processing, CSV file I/O (e.g. pd.read_csv)\n",
        "\n",
        "from tensorflow.keras.preprocessing.text import Tokenizer\n",
        "from tensorflow.keras.preprocessing.sequence import pad_sequences\n",
        "\n",
        "from keras.models import Sequential\n",
        "from keras.layers import Dense, Embedding, LSTM, SpatialDropout1D\n",
        "from matplotlib import pyplot\n",
        "from sklearn.model_selection import train_test_split\n",
        "#from keras.utils.np_utils import to_categorical\n",
        "from tensorflow.keras.utils import to_categorical\n",
        "import re\n",
        "\n",
        "from sklearn.preprocessing import LabelEncoder\n",
        "\n",
        "data = pd.read_csv('Data.csv')\n",
        "# Keeping only the neccessary columns\n",
        "data = data[['text','sentiment']]\n",
        "\n",
        "data['text'] = data['text'].apply(lambda x: x.lower())\n",
        "data['text'] = data['text'].apply((lambda x: re.sub('[^a-zA-z0-9\\s]', '', x)))\n",
        "\n",
        "for idx, row in data.iterrows():\n",
        "    row[0] = row[0].replace('rt', ' ')\n",
        "\n",
        "max_fatures = 2000\n",
        "tokenizer = Tokenizer(num_words=max_fatures, split=' ')\n",
        "tokenizer.fit_on_texts(data['text'].values)\n",
        "X = tokenizer.texts_to_sequences(data['text'].values)\n",
        "\n",
        "X = pad_sequences(X)\n",
        "\n",
        "embed_dim = 128\n",
        "lstm_out = 196\n",
        "def createmodel():\n",
        "    model = Sequential()\n",
        "    model.add(Embedding(max_fatures, embed_dim,input_length = X.shape[1]))\n",
        "    model.add(LSTM(lstm_out, dropout=0.2, recurrent_dropout=0.2))\n",
        "    model.add(Dense(3,activation='softmax'))\n",
        "    model.compile(loss = 'categorical_crossentropy', optimizer='adam',metrics = ['accuracy'])\n",
        "    return model\n",
        "# print(model.summary())\n",
        "\n",
        "labelencoder = LabelEncoder()\n",
        "integer_encoded = labelencoder.fit_transform(data['sentiment'])\n",
        "y = to_categorical(integer_encoded)\n",
        "X_train, X_test, Y_train, Y_test = train_test_split(X,y, test_size = 0.33, random_state = 42)\n",
        "\n",
        "batch_size = 32\n",
        "model = createmodel()\n",
        "model.fit(X_train, Y_train, epochs = 1, batch_size=batch_size, verbose = 2)\n",
        "score,acc = model.evaluate(X_test,Y_test,verbose=2,batch_size=batch_size)\n",
        "print(score)\n",
        "print(acc)\n",
        "print(model.metrics_names)"
      ]
    },
    {
      "cell_type": "code",
      "source": [
        "labelencoder = LabelEncoder()\n",
        "integer_encoded = labelencoder.fit_transform(data['sentiment'])\n",
        "y = to_categorical(integer_encoded)\n",
        "X_train, X_test, Y_train, Y_test = train_test_split(X,y, test_size = 0.33, random_state = 42)\n",
        "\n",
        "batch_size = 32\n",
        "model = createmodel()\n",
        "model.fit(X_train, Y_train, epochs = 1, batch_size=batch_size, verbose = 2)\n",
        "\n",
        "\n",
        "model.save('sentiment_analysis_model.h5')\n",
        "\n",
        "from tensorflow import keras\n",
        "model = keras.models.load_model('sentiment_analysis_model.h5')\n",
        "\n",
        "new_text = [\"A lot of good things are happening. We are respected again throughout the world, and that's a great thing .@realDonaldTrump\"]\n",
        "\n",
        "new_text_sequences = tokenizer.texts_to_sequences(new_text)\n",
        "new_text_padded = pad_sequences(new_text_sequences, maxlen=X.shape[1])\n",
        "\n",
        "\n",
        "predictions = model.predict(new_text_padded)\n",
        "\n",
        "\n",
        "predicted_labels = np.argmax(predictions, axis=1)\n",
        "\n",
        "predicted_sentiments = labelencoder.inverse_transform(predicted_labels)\n",
        "\n",
        "predicted_sentiments\n"
      ],
      "metadata": {
        "colab": {
          "base_uri": "https://localhost:8080/"
        },
        "id": "cA_5zFZTWTkh",
        "outputId": "b033d08a-45bd-4b2c-febe-dbb8692bf469"
      },
      "execution_count": 23,
      "outputs": [
        {
          "output_type": "stream",
          "name": "stderr",
          "text": [
            "/usr/local/lib/python3.11/dist-packages/keras/src/layers/core/embedding.py:90: UserWarning: Argument `input_length` is deprecated. Just remove it.\n",
            "  warnings.warn(\n"
          ]
        },
        {
          "output_type": "stream",
          "name": "stdout",
          "text": [
            "291/291 - 57s - 197ms/step - accuracy: 0.6403 - loss: 0.8319\n"
          ]
        },
        {
          "output_type": "stream",
          "name": "stderr",
          "text": [
            "WARNING:absl:You are saving your model as an HDF5 file via `model.save()` or `keras.saving.save_model(model)`. This file format is considered legacy. We recommend using instead the native Keras format, e.g. `model.save('my_model.keras')` or `keras.saving.save_model(model, 'my_model.keras')`. \n",
            "WARNING:absl:Compiled the loaded model, but the compiled metrics have yet to be built. `model.compile_metrics` will be empty until you train or evaluate the model.\n"
          ]
        },
        {
          "output_type": "stream",
          "name": "stdout",
          "text": [
            "\u001b[1m1/1\u001b[0m \u001b[32m━━━━━━━━━━━━━━━━━━━━\u001b[0m\u001b[37m\u001b[0m \u001b[1m0s\u001b[0m 440ms/step\n"
          ]
        },
        {
          "output_type": "execute_result",
          "data": {
            "text/plain": [
              "array(['Negative'], dtype=object)"
            ]
          },
          "metadata": {},
          "execution_count": 23
        }
      ]
    },
    {
      "cell_type": "code",
      "source": [
        "!pip install -U scikit-learn==1.4.2 scikeras==0.12.0\n"
      ],
      "metadata": {
        "colab": {
          "base_uri": "https://localhost:8080/"
        },
        "id": "QRWlld2oUVj-",
        "outputId": "2c540c35-edfb-4032-f5d0-6de6d2a54972"
      },
      "execution_count": 1,
      "outputs": [
        {
          "output_type": "stream",
          "name": "stdout",
          "text": [
            "Requirement already satisfied: scikit-learn==1.4.2 in /usr/local/lib/python3.11/dist-packages (1.4.2)\n",
            "Requirement already satisfied: scikeras==0.12.0 in /usr/local/lib/python3.11/dist-packages (0.12.0)\n",
            "Requirement already satisfied: numpy>=1.19.5 in /usr/local/lib/python3.11/dist-packages (from scikit-learn==1.4.2) (2.0.2)\n",
            "Requirement already satisfied: scipy>=1.6.0 in /usr/local/lib/python3.11/dist-packages (from scikit-learn==1.4.2) (1.15.2)\n",
            "Requirement already satisfied: joblib>=1.2.0 in /usr/local/lib/python3.11/dist-packages (from scikit-learn==1.4.2) (1.4.2)\n",
            "Requirement already satisfied: threadpoolctl>=2.0.0 in /usr/local/lib/python3.11/dist-packages (from scikit-learn==1.4.2) (3.6.0)\n",
            "Requirement already satisfied: packaging>=0.21 in /usr/local/lib/python3.11/dist-packages (from scikeras==0.12.0) (24.2)\n"
          ]
        }
      ]
    },
    {
      "cell_type": "code",
      "source": [
        "\n",
        "\n",
        "import pandas as pd\n",
        "from tensorflow.keras.preprocessing.text import Tokenizer\n",
        "from tensorflow.keras.preprocessing.sequence import pad_sequences\n",
        "from tensorflow.keras.models import Sequential\n",
        "from tensorflow.keras.layers import Dense, Embedding, LSTM, SpatialDropout1D\n",
        "from sklearn.model_selection import train_test_split, GridSearchCV\n",
        "from scikeras.wrappers import KerasClassifier\n",
        "from tensorflow.keras.utils import to_categorical\n",
        "import re\n",
        "from sklearn.preprocessing import LabelEncoder\n",
        "import numpy as np\n",
        "\n",
        "# Load the data\n",
        "data = pd.read_csv('Data.csv')\n",
        "data = data[['text','sentiment']]\n",
        "\n",
        "data['text'] = data['text'].apply(lambda x: x.lower())\n",
        "data['text'] = data['text'].apply((lambda x: re.sub('[^a-zA-z0-9\\s]', '', x)))\n",
        "\n",
        "data['text'] = data['text'].str.replace('rt', ' ', regex=False)\n",
        "\n",
        "\n",
        "max_fatures = 2000\n",
        "tokenizer = Tokenizer(num_words=max_fatures, split=' ')\n",
        "tokenizer.fit_on_texts(data['text'].values)\n",
        "X = tokenizer.texts_to_sequences(data['text'].values)\n",
        "X = pad_sequences(X)\n",
        "\n",
        "labelencoder = LabelEncoder()\n",
        "integer_encoded = labelencoder.fit_transform(data['sentiment'])\n",
        "y = integer_encoded\n",
        "\n",
        "X_train, X_test, Y_train, Y_test = train_test_split(\n",
        "    X, y, test_size=0.33, random_state=42\n",
        ")\n",
        "\n",
        "\n",
        "\n",
        "def create_model(embed_dim=128, lstm_out=196, input_length=None, max_features=2000):\n",
        "    model = Sequential()\n",
        "    model.add(Embedding(max_features, embed_dim, input_length=input_length))\n",
        "    model.add(LSTM(lstm_out, dropout=0.2, recurrent_dropout=0.2))\n",
        "    model.add(Dense(3, activation='softmax'))\n",
        "    model.compile(loss='categorical_crossentropy', optimizer='adam', metrics=['accuracy'])\n",
        "    return model\n",
        "\n",
        "\n",
        "\n",
        "model = KerasClassifier(\n",
        "    model=create_model,\n",
        "    verbose=0,\n",
        "    model__input_length=X.shape[1],\n",
        "    model__max_features=max_fatures\n",
        ")\n",
        "\n",
        "param_grid = {\n",
        "    'model__embed_dim': [64, 128],\n",
        "    'model__lstm_out': [64, 128],\n",
        "    'batch_size': [16, 32],\n",
        "    'epochs': [1, 2]\n",
        "\n",
        "}\n",
        "\n",
        "grid = GridSearchCV(\n",
        "    estimator=model,\n",
        "    param_grid=param_grid,\n",
        "    cv=3,\n",
        "    n_jobs=-1,\n",
        "    error_score='raise'\n",
        ")\n",
        "\n",
        "grid_result = grid.fit(X_train, Y_train)\n",
        "\n",
        "\n",
        "print(\"Best score: %f using %s\" % (grid_result.best_score_, grid_result.best_params_))\n",
        "\n",
        "means = grid_result.cv_results_['mean_test_score']\n",
        "stds = grid_result.cv_results_['std_test_score']\n",
        "params = grid_result.cv_results_['params']\n",
        "\n",
        "for mean, stdev, param in zip(means, stds, params):\n",
        "    print(\"%f (%f) with: %r\" % (mean, stdev, param))\n"
      ],
      "metadata": {
        "colab": {
          "base_uri": "https://localhost:8080/",
          "height": 1000
        },
        "id": "yd1CDdpzPjvN",
        "outputId": "a3f2b884-6d48-43f4-f6ff-816999751ce1"
      },
      "execution_count": 24,
      "outputs": [
        {
          "output_type": "error",
          "ename": "AttributeError",
          "evalue": "Sequential model 'sequential' has no defined outputs yet.",
          "traceback": [
            "\u001b[0;31m---------------------------------------------------------------------------\u001b[0m",
            "\u001b[0;31m_RemoteTraceback\u001b[0m                          Traceback (most recent call last)",
            "\u001b[0;31m_RemoteTraceback\u001b[0m: \n\"\"\"\nTraceback (most recent call last):\n  File \"/usr/local/lib/python3.11/dist-packages/joblib/externals/loky/process_executor.py\", line 463, in _process_worker\n    r = call_item()\n        ^^^^^^^^^^^\n  File \"/usr/local/lib/python3.11/dist-packages/joblib/externals/loky/process_executor.py\", line 291, in __call__\n    return self.fn(*self.args, **self.kwargs)\n           ^^^^^^^^^^^^^^^^^^^^^^^^^^^^^^^^^^\n  File \"/usr/local/lib/python3.11/dist-packages/joblib/parallel.py\", line 598, in __call__\n    return [func(*args, **kwargs)\n           ^^^^^^^^^^^^^^^^^^^^^^\n  File \"/usr/local/lib/python3.11/dist-packages/joblib/parallel.py\", line 598, in <listcomp>\n    return [func(*args, **kwargs)\n            ^^^^^^^^^^^^^^^^^^^^^\n  File \"/usr/local/lib/python3.11/dist-packages/sklearn/utils/parallel.py\", line 129, in __call__\n    return self.function(*args, **kwargs)\n           ^^^^^^^^^^^^^^^^^^^^^^^^^^^^^^\n  File \"/usr/local/lib/python3.11/dist-packages/sklearn/model_selection/_validation.py\", line 895, in _fit_and_score\n    estimator.fit(X_train, y_train, **fit_params)\n  File \"/usr/local/lib/python3.11/dist-packages/scikeras/wrappers.py\", line 1491, in fit\n    super().fit(X=X, y=y, sample_weight=sample_weight, **kwargs)\n  File \"/usr/local/lib/python3.11/dist-packages/scikeras/wrappers.py\", line 760, in fit\n    self._fit(\n  File \"/usr/local/lib/python3.11/dist-packages/scikeras/wrappers.py\", line 926, in _fit\n    self._check_model_compatibility(y)\n  File \"/usr/local/lib/python3.11/dist-packages/scikeras/wrappers.py\", line 549, in _check_model_compatibility\n    if self.n_outputs_expected_ != len(self.model_.outputs):\n                                       ^^^^^^^^^^^^^^^^^^^\n  File \"/usr/local/lib/python3.11/dist-packages/keras/src/models/sequential.py\", line 308, in outputs\n    raise AttributeError(\nAttributeError: Sequential model 'sequential' has no defined outputs yet.\n\"\"\"",
            "\nThe above exception was the direct cause of the following exception:\n",
            "\u001b[0;31mAttributeError\u001b[0m                            Traceback (most recent call last)",
            "\u001b[0;32m<ipython-input-24-683334edb4b6>\u001b[0m in \u001b[0;36m<cell line: 0>\u001b[0;34m()\u001b[0m\n\u001b[1;32m     70\u001b[0m ) \n\u001b[1;32m     71\u001b[0m \u001b[0;34m\u001b[0m\u001b[0m\n\u001b[0;32m---> 72\u001b[0;31m \u001b[0mgrid_result\u001b[0m \u001b[0;34m=\u001b[0m \u001b[0mgrid\u001b[0m\u001b[0;34m.\u001b[0m\u001b[0mfit\u001b[0m\u001b[0;34m(\u001b[0m\u001b[0mX_train\u001b[0m\u001b[0;34m,\u001b[0m \u001b[0mY_train\u001b[0m\u001b[0;34m)\u001b[0m\u001b[0;34m\u001b[0m\u001b[0;34m\u001b[0m\u001b[0m\n\u001b[0m\u001b[1;32m     73\u001b[0m \u001b[0;34m\u001b[0m\u001b[0m\n\u001b[1;32m     74\u001b[0m \u001b[0;34m\u001b[0m\u001b[0m\n",
            "\u001b[0;32m/usr/local/lib/python3.11/dist-packages/sklearn/base.py\u001b[0m in \u001b[0;36mwrapper\u001b[0;34m(estimator, *args, **kwargs)\u001b[0m\n\u001b[1;32m   1472\u001b[0m                 )\n\u001b[1;32m   1473\u001b[0m             ):\n\u001b[0;32m-> 1474\u001b[0;31m                 \u001b[0;32mreturn\u001b[0m \u001b[0mfit_method\u001b[0m\u001b[0;34m(\u001b[0m\u001b[0mestimator\u001b[0m\u001b[0;34m,\u001b[0m \u001b[0;34m*\u001b[0m\u001b[0margs\u001b[0m\u001b[0;34m,\u001b[0m \u001b[0;34m**\u001b[0m\u001b[0mkwargs\u001b[0m\u001b[0;34m)\u001b[0m\u001b[0;34m\u001b[0m\u001b[0;34m\u001b[0m\u001b[0m\n\u001b[0m\u001b[1;32m   1475\u001b[0m \u001b[0;34m\u001b[0m\u001b[0m\n\u001b[1;32m   1476\u001b[0m         \u001b[0;32mreturn\u001b[0m \u001b[0mwrapper\u001b[0m\u001b[0;34m\u001b[0m\u001b[0;34m\u001b[0m\u001b[0m\n",
            "\u001b[0;32m/usr/local/lib/python3.11/dist-packages/sklearn/model_selection/_search.py\u001b[0m in \u001b[0;36mfit\u001b[0;34m(self, X, y, **params)\u001b[0m\n\u001b[1;32m    968\u001b[0m                 \u001b[0;32mreturn\u001b[0m \u001b[0mresults\u001b[0m\u001b[0;34m\u001b[0m\u001b[0;34m\u001b[0m\u001b[0m\n\u001b[1;32m    969\u001b[0m \u001b[0;34m\u001b[0m\u001b[0m\n\u001b[0;32m--> 970\u001b[0;31m             \u001b[0mself\u001b[0m\u001b[0;34m.\u001b[0m\u001b[0m_run_search\u001b[0m\u001b[0;34m(\u001b[0m\u001b[0mevaluate_candidates\u001b[0m\u001b[0;34m)\u001b[0m\u001b[0;34m\u001b[0m\u001b[0;34m\u001b[0m\u001b[0m\n\u001b[0m\u001b[1;32m    971\u001b[0m \u001b[0;34m\u001b[0m\u001b[0m\n\u001b[1;32m    972\u001b[0m             \u001b[0;31m# multimetric is determined here because in the case of a callable\u001b[0m\u001b[0;34m\u001b[0m\u001b[0;34m\u001b[0m\u001b[0m\n",
            "\u001b[0;32m/usr/local/lib/python3.11/dist-packages/sklearn/model_selection/_search.py\u001b[0m in \u001b[0;36m_run_search\u001b[0;34m(self, evaluate_candidates)\u001b[0m\n\u001b[1;32m   1525\u001b[0m     \u001b[0;32mdef\u001b[0m \u001b[0m_run_search\u001b[0m\u001b[0;34m(\u001b[0m\u001b[0mself\u001b[0m\u001b[0;34m,\u001b[0m \u001b[0mevaluate_candidates\u001b[0m\u001b[0;34m)\u001b[0m\u001b[0;34m:\u001b[0m\u001b[0;34m\u001b[0m\u001b[0;34m\u001b[0m\u001b[0m\n\u001b[1;32m   1526\u001b[0m         \u001b[0;34m\"\"\"Search all candidates in param_grid\"\"\"\u001b[0m\u001b[0;34m\u001b[0m\u001b[0;34m\u001b[0m\u001b[0m\n\u001b[0;32m-> 1527\u001b[0;31m         \u001b[0mevaluate_candidates\u001b[0m\u001b[0;34m(\u001b[0m\u001b[0mParameterGrid\u001b[0m\u001b[0;34m(\u001b[0m\u001b[0mself\u001b[0m\u001b[0;34m.\u001b[0m\u001b[0mparam_grid\u001b[0m\u001b[0;34m)\u001b[0m\u001b[0;34m)\u001b[0m\u001b[0;34m\u001b[0m\u001b[0;34m\u001b[0m\u001b[0m\n\u001b[0m\u001b[1;32m   1528\u001b[0m \u001b[0;34m\u001b[0m\u001b[0m\n\u001b[1;32m   1529\u001b[0m \u001b[0;34m\u001b[0m\u001b[0m\n",
            "\u001b[0;32m/usr/local/lib/python3.11/dist-packages/sklearn/model_selection/_search.py\u001b[0m in \u001b[0;36mevaluate_candidates\u001b[0;34m(candidate_params, cv, more_results)\u001b[0m\n\u001b[1;32m    914\u001b[0m                     )\n\u001b[1;32m    915\u001b[0m \u001b[0;34m\u001b[0m\u001b[0m\n\u001b[0;32m--> 916\u001b[0;31m                 out = parallel(\n\u001b[0m\u001b[1;32m    917\u001b[0m                     delayed(_fit_and_score)(\n\u001b[1;32m    918\u001b[0m                         \u001b[0mclone\u001b[0m\u001b[0;34m(\u001b[0m\u001b[0mbase_estimator\u001b[0m\u001b[0;34m)\u001b[0m\u001b[0;34m,\u001b[0m\u001b[0;34m\u001b[0m\u001b[0;34m\u001b[0m\u001b[0m\n",
            "\u001b[0;32m/usr/local/lib/python3.11/dist-packages/sklearn/utils/parallel.py\u001b[0m in \u001b[0;36m__call__\u001b[0;34m(self, iterable)\u001b[0m\n\u001b[1;32m     65\u001b[0m             \u001b[0;32mfor\u001b[0m \u001b[0mdelayed_func\u001b[0m\u001b[0;34m,\u001b[0m \u001b[0margs\u001b[0m\u001b[0;34m,\u001b[0m \u001b[0mkwargs\u001b[0m \u001b[0;32min\u001b[0m \u001b[0miterable\u001b[0m\u001b[0;34m\u001b[0m\u001b[0;34m\u001b[0m\u001b[0m\n\u001b[1;32m     66\u001b[0m         )\n\u001b[0;32m---> 67\u001b[0;31m         \u001b[0;32mreturn\u001b[0m \u001b[0msuper\u001b[0m\u001b[0;34m(\u001b[0m\u001b[0;34m)\u001b[0m\u001b[0;34m.\u001b[0m\u001b[0m__call__\u001b[0m\u001b[0;34m(\u001b[0m\u001b[0miterable_with_config\u001b[0m\u001b[0;34m)\u001b[0m\u001b[0;34m\u001b[0m\u001b[0;34m\u001b[0m\u001b[0m\n\u001b[0m\u001b[1;32m     68\u001b[0m \u001b[0;34m\u001b[0m\u001b[0m\n\u001b[1;32m     69\u001b[0m \u001b[0;34m\u001b[0m\u001b[0m\n",
            "\u001b[0;32m/usr/local/lib/python3.11/dist-packages/joblib/parallel.py\u001b[0m in \u001b[0;36m__call__\u001b[0;34m(self, iterable)\u001b[0m\n\u001b[1;32m   2005\u001b[0m         \u001b[0mnext\u001b[0m\u001b[0;34m(\u001b[0m\u001b[0moutput\u001b[0m\u001b[0;34m)\u001b[0m\u001b[0;34m\u001b[0m\u001b[0;34m\u001b[0m\u001b[0m\n\u001b[1;32m   2006\u001b[0m \u001b[0;34m\u001b[0m\u001b[0m\n\u001b[0;32m-> 2007\u001b[0;31m         \u001b[0;32mreturn\u001b[0m \u001b[0moutput\u001b[0m \u001b[0;32mif\u001b[0m \u001b[0mself\u001b[0m\u001b[0;34m.\u001b[0m\u001b[0mreturn_generator\u001b[0m \u001b[0;32melse\u001b[0m \u001b[0mlist\u001b[0m\u001b[0;34m(\u001b[0m\u001b[0moutput\u001b[0m\u001b[0;34m)\u001b[0m\u001b[0;34m\u001b[0m\u001b[0;34m\u001b[0m\u001b[0m\n\u001b[0m\u001b[1;32m   2008\u001b[0m \u001b[0;34m\u001b[0m\u001b[0m\n\u001b[1;32m   2009\u001b[0m     \u001b[0;32mdef\u001b[0m \u001b[0m__repr__\u001b[0m\u001b[0;34m(\u001b[0m\u001b[0mself\u001b[0m\u001b[0;34m)\u001b[0m\u001b[0;34m:\u001b[0m\u001b[0;34m\u001b[0m\u001b[0;34m\u001b[0m\u001b[0m\n",
            "\u001b[0;32m/usr/local/lib/python3.11/dist-packages/joblib/parallel.py\u001b[0m in \u001b[0;36m_get_outputs\u001b[0;34m(self, iterator, pre_dispatch)\u001b[0m\n\u001b[1;32m   1648\u001b[0m \u001b[0;34m\u001b[0m\u001b[0m\n\u001b[1;32m   1649\u001b[0m             \u001b[0;32mwith\u001b[0m \u001b[0mself\u001b[0m\u001b[0;34m.\u001b[0m\u001b[0m_backend\u001b[0m\u001b[0;34m.\u001b[0m\u001b[0mretrieval_context\u001b[0m\u001b[0;34m(\u001b[0m\u001b[0;34m)\u001b[0m\u001b[0;34m:\u001b[0m\u001b[0;34m\u001b[0m\u001b[0;34m\u001b[0m\u001b[0m\n\u001b[0;32m-> 1650\u001b[0;31m                 \u001b[0;32myield\u001b[0m \u001b[0;32mfrom\u001b[0m \u001b[0mself\u001b[0m\u001b[0;34m.\u001b[0m\u001b[0m_retrieve\u001b[0m\u001b[0;34m(\u001b[0m\u001b[0;34m)\u001b[0m\u001b[0;34m\u001b[0m\u001b[0;34m\u001b[0m\u001b[0m\n\u001b[0m\u001b[1;32m   1651\u001b[0m \u001b[0;34m\u001b[0m\u001b[0m\n\u001b[1;32m   1652\u001b[0m         \u001b[0;32mexcept\u001b[0m \u001b[0mGeneratorExit\u001b[0m\u001b[0;34m:\u001b[0m\u001b[0;34m\u001b[0m\u001b[0;34m\u001b[0m\u001b[0m\n",
            "\u001b[0;32m/usr/local/lib/python3.11/dist-packages/joblib/parallel.py\u001b[0m in \u001b[0;36m_retrieve\u001b[0;34m(self)\u001b[0m\n\u001b[1;32m   1752\u001b[0m             \u001b[0;31m# worker traceback.\u001b[0m\u001b[0;34m\u001b[0m\u001b[0;34m\u001b[0m\u001b[0m\n\u001b[1;32m   1753\u001b[0m             \u001b[0;32mif\u001b[0m \u001b[0mself\u001b[0m\u001b[0;34m.\u001b[0m\u001b[0m_aborting\u001b[0m\u001b[0;34m:\u001b[0m\u001b[0;34m\u001b[0m\u001b[0;34m\u001b[0m\u001b[0m\n\u001b[0;32m-> 1754\u001b[0;31m                 \u001b[0mself\u001b[0m\u001b[0;34m.\u001b[0m\u001b[0m_raise_error_fast\u001b[0m\u001b[0;34m(\u001b[0m\u001b[0;34m)\u001b[0m\u001b[0;34m\u001b[0m\u001b[0;34m\u001b[0m\u001b[0m\n\u001b[0m\u001b[1;32m   1755\u001b[0m                 \u001b[0;32mbreak\u001b[0m\u001b[0;34m\u001b[0m\u001b[0;34m\u001b[0m\u001b[0m\n\u001b[1;32m   1756\u001b[0m \u001b[0;34m\u001b[0m\u001b[0m\n",
            "\u001b[0;32m/usr/local/lib/python3.11/dist-packages/joblib/parallel.py\u001b[0m in \u001b[0;36m_raise_error_fast\u001b[0;34m(self)\u001b[0m\n\u001b[1;32m   1787\u001b[0m         \u001b[0;31m# called directly or if the generator is gc'ed.\u001b[0m\u001b[0;34m\u001b[0m\u001b[0;34m\u001b[0m\u001b[0m\n\u001b[1;32m   1788\u001b[0m         \u001b[0;32mif\u001b[0m \u001b[0merror_job\u001b[0m \u001b[0;32mis\u001b[0m \u001b[0;32mnot\u001b[0m \u001b[0;32mNone\u001b[0m\u001b[0;34m:\u001b[0m\u001b[0;34m\u001b[0m\u001b[0;34m\u001b[0m\u001b[0m\n\u001b[0;32m-> 1789\u001b[0;31m             \u001b[0merror_job\u001b[0m\u001b[0;34m.\u001b[0m\u001b[0mget_result\u001b[0m\u001b[0;34m(\u001b[0m\u001b[0mself\u001b[0m\u001b[0;34m.\u001b[0m\u001b[0mtimeout\u001b[0m\u001b[0;34m)\u001b[0m\u001b[0;34m\u001b[0m\u001b[0;34m\u001b[0m\u001b[0m\n\u001b[0m\u001b[1;32m   1790\u001b[0m \u001b[0;34m\u001b[0m\u001b[0m\n\u001b[1;32m   1791\u001b[0m     \u001b[0;32mdef\u001b[0m \u001b[0m_warn_exit_early\u001b[0m\u001b[0;34m(\u001b[0m\u001b[0mself\u001b[0m\u001b[0;34m)\u001b[0m\u001b[0;34m:\u001b[0m\u001b[0;34m\u001b[0m\u001b[0;34m\u001b[0m\u001b[0m\n",
            "\u001b[0;32m/usr/local/lib/python3.11/dist-packages/joblib/parallel.py\u001b[0m in \u001b[0;36mget_result\u001b[0;34m(self, timeout)\u001b[0m\n\u001b[1;32m    743\u001b[0m             \u001b[0;31m# callback thread, and is stored internally. It's just waiting to\u001b[0m\u001b[0;34m\u001b[0m\u001b[0;34m\u001b[0m\u001b[0m\n\u001b[1;32m    744\u001b[0m             \u001b[0;31m# be returned.\u001b[0m\u001b[0;34m\u001b[0m\u001b[0;34m\u001b[0m\u001b[0m\n\u001b[0;32m--> 745\u001b[0;31m             \u001b[0;32mreturn\u001b[0m \u001b[0mself\u001b[0m\u001b[0;34m.\u001b[0m\u001b[0m_return_or_raise\u001b[0m\u001b[0;34m(\u001b[0m\u001b[0;34m)\u001b[0m\u001b[0;34m\u001b[0m\u001b[0;34m\u001b[0m\u001b[0m\n\u001b[0m\u001b[1;32m    746\u001b[0m \u001b[0;34m\u001b[0m\u001b[0m\n\u001b[1;32m    747\u001b[0m         \u001b[0;31m# For other backends, the main thread needs to run the retrieval step.\u001b[0m\u001b[0;34m\u001b[0m\u001b[0;34m\u001b[0m\u001b[0m\n",
            "\u001b[0;32m/usr/local/lib/python3.11/dist-packages/joblib/parallel.py\u001b[0m in \u001b[0;36m_return_or_raise\u001b[0;34m(self)\u001b[0m\n\u001b[1;32m    761\u001b[0m         \u001b[0;32mtry\u001b[0m\u001b[0;34m:\u001b[0m\u001b[0;34m\u001b[0m\u001b[0;34m\u001b[0m\u001b[0m\n\u001b[1;32m    762\u001b[0m             \u001b[0;32mif\u001b[0m \u001b[0mself\u001b[0m\u001b[0;34m.\u001b[0m\u001b[0mstatus\u001b[0m \u001b[0;34m==\u001b[0m \u001b[0mTASK_ERROR\u001b[0m\u001b[0;34m:\u001b[0m\u001b[0;34m\u001b[0m\u001b[0;34m\u001b[0m\u001b[0m\n\u001b[0;32m--> 763\u001b[0;31m                 \u001b[0;32mraise\u001b[0m \u001b[0mself\u001b[0m\u001b[0;34m.\u001b[0m\u001b[0m_result\u001b[0m\u001b[0;34m\u001b[0m\u001b[0;34m\u001b[0m\u001b[0m\n\u001b[0m\u001b[1;32m    764\u001b[0m             \u001b[0;32mreturn\u001b[0m \u001b[0mself\u001b[0m\u001b[0;34m.\u001b[0m\u001b[0m_result\u001b[0m\u001b[0;34m\u001b[0m\u001b[0;34m\u001b[0m\u001b[0m\n\u001b[1;32m    765\u001b[0m         \u001b[0;32mfinally\u001b[0m\u001b[0;34m:\u001b[0m\u001b[0;34m\u001b[0m\u001b[0;34m\u001b[0m\u001b[0m\n",
            "\u001b[0;31mAttributeError\u001b[0m: Sequential model 'sequential' has no defined outputs yet."
          ]
        }
      ]
    },
    {
      "cell_type": "code",
      "source": [
        "import pandas as pd\n",
        "from tensorflow.keras.preprocessing.text import Tokenizer\n",
        "from tensorflow.keras.preprocessing.sequence import pad_sequences\n",
        "from tensorflow.keras.models import Sequential\n",
        "from tensorflow.keras.layers import Dense, Embedding, LSTM\n",
        "from sklearn.model_selection import train_test_split, GridSearchCV\n",
        "from scikeras.wrappers import KerasClassifier\n",
        "from sklearn.preprocessing import LabelEncoder\n",
        "import numpy as np\n",
        "import re\n",
        "\n",
        "# -------------------------------\n",
        "# Step 1: Load and preprocess data\n",
        "# -------------------------------\n",
        "\n",
        "data = pd.read_csv('Data.csv')\n",
        "data = data[['text', 'sentiment']]\n",
        "\n",
        "data['text'] = data['text'].str.lower()\n",
        "data['text'] = data['text'].apply(lambda x: re.sub('[^a-zA-Z0-9\\s]', '', x))\n",
        "data['text'] = data['text'].str.replace('rt', ' ', regex=False)\n",
        "\n",
        "# -------------------------------\n",
        "# Step 2: Tokenization\n",
        "# -------------------------------\n",
        "\n",
        "max_features = 2000  # <<< NOTE THE CORRECT VARIABLE NAME!\n",
        "\n",
        "tokenizer = Tokenizer(num_words=max_features, split=' ')\n",
        "tokenizer.fit_on_texts(data['text'].values)\n",
        "X = tokenizer.texts_to_sequences(data['text'].values)\n",
        "X = pad_sequences(X)\n",
        "\n",
        "# -------------------------------\n",
        "# Step 3: Encode labels (NO to_categorical)\n",
        "# -------------------------------\n",
        "\n",
        "labelencoder = LabelEncoder()\n",
        "integer_encoded = labelencoder.fit_transform(data['sentiment'])\n",
        "y = integer_encoded  # SciKeras expects integer labels, not one-hot\n",
        "\n",
        "X_train, X_test, Y_train, Y_test = train_test_split(\n",
        "    X, y, test_size=0.33, random_state=42\n",
        ")\n",
        "\n",
        "# -------------------------------\n",
        "# Step 4: Model-building function\n",
        "# -------------------------------\n",
        "\n",
        "def create_model(embed_dim=128, lstm_out=196, input_length=None, max_features=2000):\n",
        "    model = Sequential()\n",
        "    model.add(Embedding(max_features, embed_dim, input_length=input_length))\n",
        "    model.add(LSTM(lstm_out, dropout=0.2, recurrent_dropout=0.2))\n",
        "    model.add(Dense(3, activation='softmax'))\n",
        "    model.compile(\n",
        "        loss='categorical_crossentropy',\n",
        "        optimizer='adam',\n",
        "        metrics=['accuracy']\n",
        "    )\n",
        "    return model\n",
        "\n",
        "# -------------------------------\n",
        "# Step 5: Wrap model for SciKeras\n",
        "# -------------------------------\n",
        "\n",
        "model = KerasClassifier(\n",
        "    model=create_model,\n",
        "    verbose=0,\n",
        "    model__input_length=X.shape[1],\n",
        "    model__max_features=max_features\n",
        ")\n",
        "\n",
        "# -------------------------------\n",
        "# Step 6: Grid search\n",
        "# -------------------------------\n",
        "\n",
        "param_grid = {\n",
        "    'model__embed_dim': [64, 128],\n",
        "    'model__lstm_out': [64, 128],\n",
        "    'batch_size': [16, 32],\n",
        "    'epochs': [1, 2]\n",
        "}\n",
        "\n",
        "grid = GridSearchCV(\n",
        "    estimator=model,\n",
        "    param_grid=param_grid,\n",
        "    cv=3,\n",
        "    n_jobs=1  # safer: avoids parallelism issues while debugging\n",
        ")\n",
        "\n",
        "# -------------------------------\n",
        "# Step 7: Fit Grid Search\n",
        "# -------------------------------\n",
        "\n",
        "grid_result = grid.fit(X_train, Y_train)\n",
        "\n",
        "# -------------------------------\n",
        "# Step 8: Output best results\n",
        "# -------------------------------\n",
        "\n",
        "print(\"Best score: %f using %s\" % (grid_result.best_score_, grid_result.best_params_))\n",
        "\n",
        "means = grid_result.cv_results_['mean_test_score']\n",
        "stds = grid_result.cv_results_['std_test_score']\n",
        "params = grid_result.cv_results_['params']\n",
        "\n",
        "for mean, stdev, param in zip(means, stds, params):\n",
        "    print(\"%f (%f) with: %r\" % (mean, stdev, param))\n"
      ],
      "metadata": {
        "colab": {
          "base_uri": "https://localhost:8080/",
          "height": 1000
        },
        "id": "0vE8rqJFdO4T",
        "outputId": "7894f09e-42f2-4f8e-85fa-79eb915bb0ac"
      },
      "execution_count": 25,
      "outputs": [
        {
          "output_type": "stream",
          "name": "stderr",
          "text": [
            "/usr/local/lib/python3.11/dist-packages/keras/src/layers/core/embedding.py:90: UserWarning: Argument `input_length` is deprecated. Just remove it.\n",
            "  warnings.warn(\n",
            "/usr/local/lib/python3.11/dist-packages/keras/src/layers/core/embedding.py:90: UserWarning: Argument `input_length` is deprecated. Just remove it.\n",
            "  warnings.warn(\n",
            "/usr/local/lib/python3.11/dist-packages/keras/src/layers/core/embedding.py:90: UserWarning: Argument `input_length` is deprecated. Just remove it.\n",
            "  warnings.warn(\n",
            "/usr/local/lib/python3.11/dist-packages/keras/src/layers/core/embedding.py:90: UserWarning: Argument `input_length` is deprecated. Just remove it.\n",
            "  warnings.warn(\n",
            "/usr/local/lib/python3.11/dist-packages/keras/src/layers/core/embedding.py:90: UserWarning: Argument `input_length` is deprecated. Just remove it.\n",
            "  warnings.warn(\n",
            "/usr/local/lib/python3.11/dist-packages/keras/src/layers/core/embedding.py:90: UserWarning: Argument `input_length` is deprecated. Just remove it.\n",
            "  warnings.warn(\n",
            "/usr/local/lib/python3.11/dist-packages/keras/src/layers/core/embedding.py:90: UserWarning: Argument `input_length` is deprecated. Just remove it.\n",
            "  warnings.warn(\n",
            "/usr/local/lib/python3.11/dist-packages/keras/src/layers/core/embedding.py:90: UserWarning: Argument `input_length` is deprecated. Just remove it.\n",
            "  warnings.warn(\n",
            "/usr/local/lib/python3.11/dist-packages/keras/src/layers/core/embedding.py:90: UserWarning: Argument `input_length` is deprecated. Just remove it.\n",
            "  warnings.warn(\n",
            "/usr/local/lib/python3.11/dist-packages/keras/src/layers/core/embedding.py:90: UserWarning: Argument `input_length` is deprecated. Just remove it.\n",
            "  warnings.warn(\n",
            "/usr/local/lib/python3.11/dist-packages/keras/src/layers/core/embedding.py:90: UserWarning: Argument `input_length` is deprecated. Just remove it.\n",
            "  warnings.warn(\n",
            "/usr/local/lib/python3.11/dist-packages/keras/src/layers/core/embedding.py:90: UserWarning: Argument `input_length` is deprecated. Just remove it.\n",
            "  warnings.warn(\n",
            "/usr/local/lib/python3.11/dist-packages/keras/src/layers/core/embedding.py:90: UserWarning: Argument `input_length` is deprecated. Just remove it.\n",
            "  warnings.warn(\n",
            "/usr/local/lib/python3.11/dist-packages/keras/src/layers/core/embedding.py:90: UserWarning: Argument `input_length` is deprecated. Just remove it.\n",
            "  warnings.warn(\n",
            "/usr/local/lib/python3.11/dist-packages/keras/src/layers/core/embedding.py:90: UserWarning: Argument `input_length` is deprecated. Just remove it.\n",
            "  warnings.warn(\n",
            "/usr/local/lib/python3.11/dist-packages/keras/src/layers/core/embedding.py:90: UserWarning: Argument `input_length` is deprecated. Just remove it.\n",
            "  warnings.warn(\n",
            "/usr/local/lib/python3.11/dist-packages/keras/src/layers/core/embedding.py:90: UserWarning: Argument `input_length` is deprecated. Just remove it.\n",
            "  warnings.warn(\n",
            "/usr/local/lib/python3.11/dist-packages/keras/src/layers/core/embedding.py:90: UserWarning: Argument `input_length` is deprecated. Just remove it.\n",
            "  warnings.warn(\n",
            "/usr/local/lib/python3.11/dist-packages/keras/src/layers/core/embedding.py:90: UserWarning: Argument `input_length` is deprecated. Just remove it.\n",
            "  warnings.warn(\n",
            "/usr/local/lib/python3.11/dist-packages/keras/src/layers/core/embedding.py:90: UserWarning: Argument `input_length` is deprecated. Just remove it.\n",
            "  warnings.warn(\n",
            "/usr/local/lib/python3.11/dist-packages/keras/src/layers/core/embedding.py:90: UserWarning: Argument `input_length` is deprecated. Just remove it.\n",
            "  warnings.warn(\n",
            "/usr/local/lib/python3.11/dist-packages/keras/src/layers/core/embedding.py:90: UserWarning: Argument `input_length` is deprecated. Just remove it.\n",
            "  warnings.warn(\n",
            "/usr/local/lib/python3.11/dist-packages/keras/src/layers/core/embedding.py:90: UserWarning: Argument `input_length` is deprecated. Just remove it.\n",
            "  warnings.warn(\n",
            "/usr/local/lib/python3.11/dist-packages/keras/src/layers/core/embedding.py:90: UserWarning: Argument `input_length` is deprecated. Just remove it.\n",
            "  warnings.warn(\n",
            "/usr/local/lib/python3.11/dist-packages/keras/src/layers/core/embedding.py:90: UserWarning: Argument `input_length` is deprecated. Just remove it.\n",
            "  warnings.warn(\n",
            "/usr/local/lib/python3.11/dist-packages/keras/src/layers/core/embedding.py:90: UserWarning: Argument `input_length` is deprecated. Just remove it.\n",
            "  warnings.warn(\n",
            "/usr/local/lib/python3.11/dist-packages/keras/src/layers/core/embedding.py:90: UserWarning: Argument `input_length` is deprecated. Just remove it.\n",
            "  warnings.warn(\n",
            "/usr/local/lib/python3.11/dist-packages/keras/src/layers/core/embedding.py:90: UserWarning: Argument `input_length` is deprecated. Just remove it.\n",
            "  warnings.warn(\n",
            "/usr/local/lib/python3.11/dist-packages/keras/src/layers/core/embedding.py:90: UserWarning: Argument `input_length` is deprecated. Just remove it.\n",
            "  warnings.warn(\n",
            "/usr/local/lib/python3.11/dist-packages/keras/src/layers/core/embedding.py:90: UserWarning: Argument `input_length` is deprecated. Just remove it.\n",
            "  warnings.warn(\n",
            "/usr/local/lib/python3.11/dist-packages/keras/src/layers/core/embedding.py:90: UserWarning: Argument `input_length` is deprecated. Just remove it.\n",
            "  warnings.warn(\n",
            "/usr/local/lib/python3.11/dist-packages/keras/src/layers/core/embedding.py:90: UserWarning: Argument `input_length` is deprecated. Just remove it.\n",
            "  warnings.warn(\n",
            "/usr/local/lib/python3.11/dist-packages/keras/src/layers/core/embedding.py:90: UserWarning: Argument `input_length` is deprecated. Just remove it.\n",
            "  warnings.warn(\n",
            "/usr/local/lib/python3.11/dist-packages/keras/src/layers/core/embedding.py:90: UserWarning: Argument `input_length` is deprecated. Just remove it.\n",
            "  warnings.warn(\n",
            "/usr/local/lib/python3.11/dist-packages/keras/src/layers/core/embedding.py:90: UserWarning: Argument `input_length` is deprecated. Just remove it.\n",
            "  warnings.warn(\n",
            "/usr/local/lib/python3.11/dist-packages/keras/src/layers/core/embedding.py:90: UserWarning: Argument `input_length` is deprecated. Just remove it.\n",
            "  warnings.warn(\n",
            "/usr/local/lib/python3.11/dist-packages/keras/src/layers/core/embedding.py:90: UserWarning: Argument `input_length` is deprecated. Just remove it.\n",
            "  warnings.warn(\n",
            "/usr/local/lib/python3.11/dist-packages/keras/src/layers/core/embedding.py:90: UserWarning: Argument `input_length` is deprecated. Just remove it.\n",
            "  warnings.warn(\n",
            "/usr/local/lib/python3.11/dist-packages/keras/src/layers/core/embedding.py:90: UserWarning: Argument `input_length` is deprecated. Just remove it.\n",
            "  warnings.warn(\n",
            "/usr/local/lib/python3.11/dist-packages/keras/src/layers/core/embedding.py:90: UserWarning: Argument `input_length` is deprecated. Just remove it.\n",
            "  warnings.warn(\n",
            "/usr/local/lib/python3.11/dist-packages/keras/src/layers/core/embedding.py:90: UserWarning: Argument `input_length` is deprecated. Just remove it.\n",
            "  warnings.warn(\n",
            "/usr/local/lib/python3.11/dist-packages/keras/src/layers/core/embedding.py:90: UserWarning: Argument `input_length` is deprecated. Just remove it.\n",
            "  warnings.warn(\n",
            "/usr/local/lib/python3.11/dist-packages/keras/src/layers/core/embedding.py:90: UserWarning: Argument `input_length` is deprecated. Just remove it.\n",
            "  warnings.warn(\n",
            "/usr/local/lib/python3.11/dist-packages/keras/src/layers/core/embedding.py:90: UserWarning: Argument `input_length` is deprecated. Just remove it.\n",
            "  warnings.warn(\n",
            "/usr/local/lib/python3.11/dist-packages/keras/src/layers/core/embedding.py:90: UserWarning: Argument `input_length` is deprecated. Just remove it.\n",
            "  warnings.warn(\n",
            "/usr/local/lib/python3.11/dist-packages/keras/src/layers/core/embedding.py:90: UserWarning: Argument `input_length` is deprecated. Just remove it.\n",
            "  warnings.warn(\n",
            "/usr/local/lib/python3.11/dist-packages/keras/src/layers/core/embedding.py:90: UserWarning: Argument `input_length` is deprecated. Just remove it.\n",
            "  warnings.warn(\n",
            "/usr/local/lib/python3.11/dist-packages/keras/src/layers/core/embedding.py:90: UserWarning: Argument `input_length` is deprecated. Just remove it.\n",
            "  warnings.warn(\n"
          ]
        },
        {
          "output_type": "error",
          "ename": "ValueError",
          "evalue": "\nAll the 48 fits failed.\nIt is very likely that your model is misconfigured.\nYou can try to debug the error by setting error_score='raise'.\n\nBelow are more details about the failures:\n--------------------------------------------------------------------------------\n1 fits failed with the following error:\nTraceback (most recent call last):\n  File \"/usr/local/lib/python3.11/dist-packages/sklearn/model_selection/_validation.py\", line 895, in _fit_and_score\n    estimator.fit(X_train, y_train, **fit_params)\n  File \"/usr/local/lib/python3.11/dist-packages/scikeras/wrappers.py\", line 1491, in fit\n    super().fit(X=X, y=y, sample_weight=sample_weight, **kwargs)\n  File \"/usr/local/lib/python3.11/dist-packages/scikeras/wrappers.py\", line 760, in fit\n    self._fit(\n  File \"/usr/local/lib/python3.11/dist-packages/scikeras/wrappers.py\", line 926, in _fit\n    self._check_model_compatibility(y)\n  File \"/usr/local/lib/python3.11/dist-packages/scikeras/wrappers.py\", line 549, in _check_model_compatibility\n    if self.n_outputs_expected_ != len(self.model_.outputs):\n                                       ^^^^^^^^^^^^^^^^^^^\n  File \"/usr/local/lib/python3.11/dist-packages/keras/src/models/sequential.py\", line 308, in outputs\n    raise AttributeError(\nAttributeError: Sequential model 'sequential_50' has no defined outputs yet.\n\n--------------------------------------------------------------------------------\n1 fits failed with the following error:\nTraceback (most recent call last):\n  File \"/usr/local/lib/python3.11/dist-packages/sklearn/model_selection/_validation.py\", line 895, in _fit_and_score\n    estimator.fit(X_train, y_train, **fit_params)\n  File \"/usr/local/lib/python3.11/dist-packages/scikeras/wrappers.py\", line 1491, in fit\n    super().fit(X=X, y=y, sample_weight=sample_weight, **kwargs)\n  File \"/usr/local/lib/python3.11/dist-packages/scikeras/wrappers.py\", line 760, in fit\n    self._fit(\n  File \"/usr/local/lib/python3.11/dist-packages/scikeras/wrappers.py\", line 926, in _fit\n    self._check_model_compatibility(y)\n  File \"/usr/local/lib/python3.11/dist-packages/scikeras/wrappers.py\", line 549, in _check_model_compatibility\n    if self.n_outputs_expected_ != len(self.model_.outputs):\n                                       ^^^^^^^^^^^^^^^^^^^\n  File \"/usr/local/lib/python3.11/dist-packages/keras/src/models/sequential.py\", line 308, in outputs\n    raise AttributeError(\nAttributeError: Sequential model 'sequential_51' has no defined outputs yet.\n\n--------------------------------------------------------------------------------\n1 fits failed with the following error:\nTraceback (most recent call last):\n  File \"/usr/local/lib/python3.11/dist-packages/sklearn/model_selection/_validation.py\", line 895, in _fit_and_score\n    estimator.fit(X_train, y_train, **fit_params)\n  File \"/usr/local/lib/python3.11/dist-packages/scikeras/wrappers.py\", line 1491, in fit\n    super().fit(X=X, y=y, sample_weight=sample_weight, **kwargs)\n  File \"/usr/local/lib/python3.11/dist-packages/scikeras/wrappers.py\", line 760, in fit\n    self._fit(\n  File \"/usr/local/lib/python3.11/dist-packages/scikeras/wrappers.py\", line 926, in _fit\n    self._check_model_compatibility(y)\n  File \"/usr/local/lib/python3.11/dist-packages/scikeras/wrappers.py\", line 549, in _check_model_compatibility\n    if self.n_outputs_expected_ != len(self.model_.outputs):\n                                       ^^^^^^^^^^^^^^^^^^^\n  File \"/usr/local/lib/python3.11/dist-packages/keras/src/models/sequential.py\", line 308, in outputs\n    raise AttributeError(\nAttributeError: Sequential model 'sequential_52' has no defined outputs yet.\n\n--------------------------------------------------------------------------------\n1 fits failed with the following error:\nTraceback (most recent call last):\n  File \"/usr/local/lib/python3.11/dist-packages/sklearn/model_selection/_validation.py\", line 895, in _fit_and_score\n    estimator.fit(X_train, y_train, **fit_params)\n  File \"/usr/local/lib/python3.11/dist-packages/scikeras/wrappers.py\", line 1491, in fit\n    super().fit(X=X, y=y, sample_weight=sample_weight, **kwargs)\n  File \"/usr/local/lib/python3.11/dist-packages/scikeras/wrappers.py\", line 760, in fit\n    self._fit(\n  File \"/usr/local/lib/python3.11/dist-packages/scikeras/wrappers.py\", line 926, in _fit\n    self._check_model_compatibility(y)\n  File \"/usr/local/lib/python3.11/dist-packages/scikeras/wrappers.py\", line 549, in _check_model_compatibility\n    if self.n_outputs_expected_ != len(self.model_.outputs):\n                                       ^^^^^^^^^^^^^^^^^^^\n  File \"/usr/local/lib/python3.11/dist-packages/keras/src/models/sequential.py\", line 308, in outputs\n    raise AttributeError(\nAttributeError: Sequential model 'sequential_53' has no defined outputs yet.\n\n--------------------------------------------------------------------------------\n1 fits failed with the following error:\nTraceback (most recent call last):\n  File \"/usr/local/lib/python3.11/dist-packages/sklearn/model_selection/_validation.py\", line 895, in _fit_and_score\n    estimator.fit(X_train, y_train, **fit_params)\n  File \"/usr/local/lib/python3.11/dist-packages/scikeras/wrappers.py\", line 1491, in fit\n    super().fit(X=X, y=y, sample_weight=sample_weight, **kwargs)\n  File \"/usr/local/lib/python3.11/dist-packages/scikeras/wrappers.py\", line 760, in fit\n    self._fit(\n  File \"/usr/local/lib/python3.11/dist-packages/scikeras/wrappers.py\", line 926, in _fit\n    self._check_model_compatibility(y)\n  File \"/usr/local/lib/python3.11/dist-packages/scikeras/wrappers.py\", line 549, in _check_model_compatibility\n    if self.n_outputs_expected_ != len(self.model_.outputs):\n                                       ^^^^^^^^^^^^^^^^^^^\n  File \"/usr/local/lib/python3.11/dist-packages/keras/src/models/sequential.py\", line 308, in outputs\n    raise AttributeError(\nAttributeError: Sequential model 'sequential_54' has no defined outputs yet.\n\n--------------------------------------------------------------------------------\n1 fits failed with the following error:\nTraceback (most recent call last):\n  File \"/usr/local/lib/python3.11/dist-packages/sklearn/model_selection/_validation.py\", line 895, in _fit_and_score\n    estimator.fit(X_train, y_train, **fit_params)\n  File \"/usr/local/lib/python3.11/dist-packages/scikeras/wrappers.py\", line 1491, in fit\n    super().fit(X=X, y=y, sample_weight=sample_weight, **kwargs)\n  File \"/usr/local/lib/python3.11/dist-packages/scikeras/wrappers.py\", line 760, in fit\n    self._fit(\n  File \"/usr/local/lib/python3.11/dist-packages/scikeras/wrappers.py\", line 926, in _fit\n    self._check_model_compatibility(y)\n  File \"/usr/local/lib/python3.11/dist-packages/scikeras/wrappers.py\", line 549, in _check_model_compatibility\n    if self.n_outputs_expected_ != len(self.model_.outputs):\n                                       ^^^^^^^^^^^^^^^^^^^\n  File \"/usr/local/lib/python3.11/dist-packages/keras/src/models/sequential.py\", line 308, in outputs\n    raise AttributeError(\nAttributeError: Sequential model 'sequential_55' has no defined outputs yet.\n\n--------------------------------------------------------------------------------\n1 fits failed with the following error:\nTraceback (most recent call last):\n  File \"/usr/local/lib/python3.11/dist-packages/sklearn/model_selection/_validation.py\", line 895, in _fit_and_score\n    estimator.fit(X_train, y_train, **fit_params)\n  File \"/usr/local/lib/python3.11/dist-packages/scikeras/wrappers.py\", line 1491, in fit\n    super().fit(X=X, y=y, sample_weight=sample_weight, **kwargs)\n  File \"/usr/local/lib/python3.11/dist-packages/scikeras/wrappers.py\", line 760, in fit\n    self._fit(\n  File \"/usr/local/lib/python3.11/dist-packages/scikeras/wrappers.py\", line 926, in _fit\n    self._check_model_compatibility(y)\n  File \"/usr/local/lib/python3.11/dist-packages/scikeras/wrappers.py\", line 549, in _check_model_compatibility\n    if self.n_outputs_expected_ != len(self.model_.outputs):\n                                       ^^^^^^^^^^^^^^^^^^^\n  File \"/usr/local/lib/python3.11/dist-packages/keras/src/models/sequential.py\", line 308, in outputs\n    raise AttributeError(\nAttributeError: Sequential model 'sequential_56' has no defined outputs yet.\n\n--------------------------------------------------------------------------------\n1 fits failed with the following error:\nTraceback (most recent call last):\n  File \"/usr/local/lib/python3.11/dist-packages/sklearn/model_selection/_validation.py\", line 895, in _fit_and_score\n    estimator.fit(X_train, y_train, **fit_params)\n  File \"/usr/local/lib/python3.11/dist-packages/scikeras/wrappers.py\", line 1491, in fit\n    super().fit(X=X, y=y, sample_weight=sample_weight, **kwargs)\n  File \"/usr/local/lib/python3.11/dist-packages/scikeras/wrappers.py\", line 760, in fit\n    self._fit(\n  File \"/usr/local/lib/python3.11/dist-packages/scikeras/wrappers.py\", line 926, in _fit\n    self._check_model_compatibility(y)\n  File \"/usr/local/lib/python3.11/dist-packages/scikeras/wrappers.py\", line 549, in _check_model_compatibility\n    if self.n_outputs_expected_ != len(self.model_.outputs):\n                                       ^^^^^^^^^^^^^^^^^^^\n  File \"/usr/local/lib/python3.11/dist-packages/keras/src/models/sequential.py\", line 308, in outputs\n    raise AttributeError(\nAttributeError: Sequential model 'sequential_57' has no defined outputs yet.\n\n--------------------------------------------------------------------------------\n1 fits failed with the following error:\nTraceback (most recent call last):\n  File \"/usr/local/lib/python3.11/dist-packages/sklearn/model_selection/_validation.py\", line 895, in _fit_and_score\n    estimator.fit(X_train, y_train, **fit_params)\n  File \"/usr/local/lib/python3.11/dist-packages/scikeras/wrappers.py\", line 1491, in fit\n    super().fit(X=X, y=y, sample_weight=sample_weight, **kwargs)\n  File \"/usr/local/lib/python3.11/dist-packages/scikeras/wrappers.py\", line 760, in fit\n    self._fit(\n  File \"/usr/local/lib/python3.11/dist-packages/scikeras/wrappers.py\", line 926, in _fit\n    self._check_model_compatibility(y)\n  File \"/usr/local/lib/python3.11/dist-packages/scikeras/wrappers.py\", line 549, in _check_model_compatibility\n    if self.n_outputs_expected_ != len(self.model_.outputs):\n                                       ^^^^^^^^^^^^^^^^^^^\n  File \"/usr/local/lib/python3.11/dist-packages/keras/src/models/sequential.py\", line 308, in outputs\n    raise AttributeError(\nAttributeError: Sequential model 'sequential_58' has no defined outputs yet.\n\n--------------------------------------------------------------------------------\n1 fits failed with the following error:\nTraceback (most recent call last):\n  File \"/usr/local/lib/python3.11/dist-packages/sklearn/model_selection/_validation.py\", line 895, in _fit_and_score\n    estimator.fit(X_train, y_train, **fit_params)\n  File \"/usr/local/lib/python3.11/dist-packages/scikeras/wrappers.py\", line 1491, in fit\n    super().fit(X=X, y=y, sample_weight=sample_weight, **kwargs)\n  File \"/usr/local/lib/python3.11/dist-packages/scikeras/wrappers.py\", line 760, in fit\n    self._fit(\n  File \"/usr/local/lib/python3.11/dist-packages/scikeras/wrappers.py\", line 926, in _fit\n    self._check_model_compatibility(y)\n  File \"/usr/local/lib/python3.11/dist-packages/scikeras/wrappers.py\", line 549, in _check_model_compatibility\n    if self.n_outputs_expected_ != len(self.model_.outputs):\n                                       ^^^^^^^^^^^^^^^^^^^\n  File \"/usr/local/lib/python3.11/dist-packages/keras/src/models/sequential.py\", line 308, in outputs\n    raise AttributeError(\nAttributeError: Sequential model 'sequential_59' has no defined outputs yet.\n\n--------------------------------------------------------------------------------\n1 fits failed with the following error:\nTraceback (most recent call last):\n  File \"/usr/local/lib/python3.11/dist-packages/sklearn/model_selection/_validation.py\", line 895, in _fit_and_score\n    estimator.fit(X_train, y_train, **fit_params)\n  File \"/usr/local/lib/python3.11/dist-packages/scikeras/wrappers.py\", line 1491, in fit\n    super().fit(X=X, y=y, sample_weight=sample_weight, **kwargs)\n  File \"/usr/local/lib/python3.11/dist-packages/scikeras/wrappers.py\", line 760, in fit\n    self._fit(\n  File \"/usr/local/lib/python3.11/dist-packages/scikeras/wrappers.py\", line 926, in _fit\n    self._check_model_compatibility(y)\n  File \"/usr/local/lib/python3.11/dist-packages/scikeras/wrappers.py\", line 549, in _check_model_compatibility\n    if self.n_outputs_expected_ != len(self.model_.outputs):\n                                       ^^^^^^^^^^^^^^^^^^^\n  File \"/usr/local/lib/python3.11/dist-packages/keras/src/models/sequential.py\", line 308, in outputs\n    raise AttributeError(\nAttributeError: Sequential model 'sequential_60' has no defined outputs yet.\n\n--------------------------------------------------------------------------------\n1 fits failed with the following error:\nTraceback (most recent call last):\n  File \"/usr/local/lib/python3.11/dist-packages/sklearn/model_selection/_validation.py\", line 895, in _fit_and_score\n    estimator.fit(X_train, y_train, **fit_params)\n  File \"/usr/local/lib/python3.11/dist-packages/scikeras/wrappers.py\", line 1491, in fit\n    super().fit(X=X, y=y, sample_weight=sample_weight, **kwargs)\n  File \"/usr/local/lib/python3.11/dist-packages/scikeras/wrappers.py\", line 760, in fit\n    self._fit(\n  File \"/usr/local/lib/python3.11/dist-packages/scikeras/wrappers.py\", line 926, in _fit\n    self._check_model_compatibility(y)\n  File \"/usr/local/lib/python3.11/dist-packages/scikeras/wrappers.py\", line 549, in _check_model_compatibility\n    if self.n_outputs_expected_ != len(self.model_.outputs):\n                                       ^^^^^^^^^^^^^^^^^^^\n  File \"/usr/local/lib/python3.11/dist-packages/keras/src/models/sequential.py\", line 308, in outputs\n    raise AttributeError(\nAttributeError: Sequential model 'sequential_61' has no defined outputs yet.\n\n--------------------------------------------------------------------------------\n1 fits failed with the following error:\nTraceback (most recent call last):\n  File \"/usr/local/lib/python3.11/dist-packages/sklearn/model_selection/_validation.py\", line 895, in _fit_and_score\n    estimator.fit(X_train, y_train, **fit_params)\n  File \"/usr/local/lib/python3.11/dist-packages/scikeras/wrappers.py\", line 1491, in fit\n    super().fit(X=X, y=y, sample_weight=sample_weight, **kwargs)\n  File \"/usr/local/lib/python3.11/dist-packages/scikeras/wrappers.py\", line 760, in fit\n    self._fit(\n  File \"/usr/local/lib/python3.11/dist-packages/scikeras/wrappers.py\", line 926, in _fit\n    self._check_model_compatibility(y)\n  File \"/usr/local/lib/python3.11/dist-packages/scikeras/wrappers.py\", line 549, in _check_model_compatibility\n    if self.n_outputs_expected_ != len(self.model_.outputs):\n                                       ^^^^^^^^^^^^^^^^^^^\n  File \"/usr/local/lib/python3.11/dist-packages/keras/src/models/sequential.py\", line 308, in outputs\n    raise AttributeError(\nAttributeError: Sequential model 'sequential_62' has no defined outputs yet.\n\n--------------------------------------------------------------------------------\n1 fits failed with the following error:\nTraceback (most recent call last):\n  File \"/usr/local/lib/python3.11/dist-packages/sklearn/model_selection/_validation.py\", line 895, in _fit_and_score\n    estimator.fit(X_train, y_train, **fit_params)\n  File \"/usr/local/lib/python3.11/dist-packages/scikeras/wrappers.py\", line 1491, in fit\n    super().fit(X=X, y=y, sample_weight=sample_weight, **kwargs)\n  File \"/usr/local/lib/python3.11/dist-packages/scikeras/wrappers.py\", line 760, in fit\n    self._fit(\n  File \"/usr/local/lib/python3.11/dist-packages/scikeras/wrappers.py\", line 926, in _fit\n    self._check_model_compatibility(y)\n  File \"/usr/local/lib/python3.11/dist-packages/scikeras/wrappers.py\", line 549, in _check_model_compatibility\n    if self.n_outputs_expected_ != len(self.model_.outputs):\n                                       ^^^^^^^^^^^^^^^^^^^\n  File \"/usr/local/lib/python3.11/dist-packages/keras/src/models/sequential.py\", line 308, in outputs\n    raise AttributeError(\nAttributeError: Sequential model 'sequential_63' has no defined outputs yet.\n\n--------------------------------------------------------------------------------\n1 fits failed with the following error:\nTraceback (most recent call last):\n  File \"/usr/local/lib/python3.11/dist-packages/sklearn/model_selection/_validation.py\", line 895, in _fit_and_score\n    estimator.fit(X_train, y_train, **fit_params)\n  File \"/usr/local/lib/python3.11/dist-packages/scikeras/wrappers.py\", line 1491, in fit\n    super().fit(X=X, y=y, sample_weight=sample_weight, **kwargs)\n  File \"/usr/local/lib/python3.11/dist-packages/scikeras/wrappers.py\", line 760, in fit\n    self._fit(\n  File \"/usr/local/lib/python3.11/dist-packages/scikeras/wrappers.py\", line 926, in _fit\n    self._check_model_compatibility(y)\n  File \"/usr/local/lib/python3.11/dist-packages/scikeras/wrappers.py\", line 549, in _check_model_compatibility\n    if self.n_outputs_expected_ != len(self.model_.outputs):\n                                       ^^^^^^^^^^^^^^^^^^^\n  File \"/usr/local/lib/python3.11/dist-packages/keras/src/models/sequential.py\", line 308, in outputs\n    raise AttributeError(\nAttributeError: Sequential model 'sequential_64' has no defined outputs yet.\n\n--------------------------------------------------------------------------------\n1 fits failed with the following error:\nTraceback (most recent call last):\n  File \"/usr/local/lib/python3.11/dist-packages/sklearn/model_selection/_validation.py\", line 895, in _fit_and_score\n    estimator.fit(X_train, y_train, **fit_params)\n  File \"/usr/local/lib/python3.11/dist-packages/scikeras/wrappers.py\", line 1491, in fit\n    super().fit(X=X, y=y, sample_weight=sample_weight, **kwargs)\n  File \"/usr/local/lib/python3.11/dist-packages/scikeras/wrappers.py\", line 760, in fit\n    self._fit(\n  File \"/usr/local/lib/python3.11/dist-packages/scikeras/wrappers.py\", line 926, in _fit\n    self._check_model_compatibility(y)\n  File \"/usr/local/lib/python3.11/dist-packages/scikeras/wrappers.py\", line 549, in _check_model_compatibility\n    if self.n_outputs_expected_ != len(self.model_.outputs):\n                                       ^^^^^^^^^^^^^^^^^^^\n  File \"/usr/local/lib/python3.11/dist-packages/keras/src/models/sequential.py\", line 308, in outputs\n    raise AttributeError(\nAttributeError: Sequential model 'sequential_65' has no defined outputs yet.\n\n--------------------------------------------------------------------------------\n1 fits failed with the following error:\nTraceback (most recent call last):\n  File \"/usr/local/lib/python3.11/dist-packages/sklearn/model_selection/_validation.py\", line 895, in _fit_and_score\n    estimator.fit(X_train, y_train, **fit_params)\n  File \"/usr/local/lib/python3.11/dist-packages/scikeras/wrappers.py\", line 1491, in fit\n    super().fit(X=X, y=y, sample_weight=sample_weight, **kwargs)\n  File \"/usr/local/lib/python3.11/dist-packages/scikeras/wrappers.py\", line 760, in fit\n    self._fit(\n  File \"/usr/local/lib/python3.11/dist-packages/scikeras/wrappers.py\", line 926, in _fit\n    self._check_model_compatibility(y)\n  File \"/usr/local/lib/python3.11/dist-packages/scikeras/wrappers.py\", line 549, in _check_model_compatibility\n    if self.n_outputs_expected_ != len(self.model_.outputs):\n                                       ^^^^^^^^^^^^^^^^^^^\n  File \"/usr/local/lib/python3.11/dist-packages/keras/src/models/sequential.py\", line 308, in outputs\n    raise AttributeError(\nAttributeError: Sequential model 'sequential_66' has no defined outputs yet.\n\n--------------------------------------------------------------------------------\n1 fits failed with the following error:\nTraceback (most recent call last):\n  File \"/usr/local/lib/python3.11/dist-packages/sklearn/model_selection/_validation.py\", line 895, in _fit_and_score\n    estimator.fit(X_train, y_train, **fit_params)\n  File \"/usr/local/lib/python3.11/dist-packages/scikeras/wrappers.py\", line 1491, in fit\n    super().fit(X=X, y=y, sample_weight=sample_weight, **kwargs)\n  File \"/usr/local/lib/python3.11/dist-packages/scikeras/wrappers.py\", line 760, in fit\n    self._fit(\n  File \"/usr/local/lib/python3.11/dist-packages/scikeras/wrappers.py\", line 926, in _fit\n    self._check_model_compatibility(y)\n  File \"/usr/local/lib/python3.11/dist-packages/scikeras/wrappers.py\", line 549, in _check_model_compatibility\n    if self.n_outputs_expected_ != len(self.model_.outputs):\n                                       ^^^^^^^^^^^^^^^^^^^\n  File \"/usr/local/lib/python3.11/dist-packages/keras/src/models/sequential.py\", line 308, in outputs\n    raise AttributeError(\nAttributeError: Sequential model 'sequential_67' has no defined outputs yet.\n\n--------------------------------------------------------------------------------\n1 fits failed with the following error:\nTraceback (most recent call last):\n  File \"/usr/local/lib/python3.11/dist-packages/sklearn/model_selection/_validation.py\", line 895, in _fit_and_score\n    estimator.fit(X_train, y_train, **fit_params)\n  File \"/usr/local/lib/python3.11/dist-packages/scikeras/wrappers.py\", line 1491, in fit\n    super().fit(X=X, y=y, sample_weight=sample_weight, **kwargs)\n  File \"/usr/local/lib/python3.11/dist-packages/scikeras/wrappers.py\", line 760, in fit\n    self._fit(\n  File \"/usr/local/lib/python3.11/dist-packages/scikeras/wrappers.py\", line 926, in _fit\n    self._check_model_compatibility(y)\n  File \"/usr/local/lib/python3.11/dist-packages/scikeras/wrappers.py\", line 549, in _check_model_compatibility\n    if self.n_outputs_expected_ != len(self.model_.outputs):\n                                       ^^^^^^^^^^^^^^^^^^^\n  File \"/usr/local/lib/python3.11/dist-packages/keras/src/models/sequential.py\", line 308, in outputs\n    raise AttributeError(\nAttributeError: Sequential model 'sequential_68' has no defined outputs yet.\n\n--------------------------------------------------------------------------------\n1 fits failed with the following error:\nTraceback (most recent call last):\n  File \"/usr/local/lib/python3.11/dist-packages/sklearn/model_selection/_validation.py\", line 895, in _fit_and_score\n    estimator.fit(X_train, y_train, **fit_params)\n  File \"/usr/local/lib/python3.11/dist-packages/scikeras/wrappers.py\", line 1491, in fit\n    super().fit(X=X, y=y, sample_weight=sample_weight, **kwargs)\n  File \"/usr/local/lib/python3.11/dist-packages/scikeras/wrappers.py\", line 760, in fit\n    self._fit(\n  File \"/usr/local/lib/python3.11/dist-packages/scikeras/wrappers.py\", line 926, in _fit\n    self._check_model_compatibility(y)\n  File \"/usr/local/lib/python3.11/dist-packages/scikeras/wrappers.py\", line 549, in _check_model_compatibility\n    if self.n_outputs_expected_ != len(self.model_.outputs):\n                                       ^^^^^^^^^^^^^^^^^^^\n  File \"/usr/local/lib/python3.11/dist-packages/keras/src/models/sequential.py\", line 308, in outputs\n    raise AttributeError(\nAttributeError: Sequential model 'sequential_69' has no defined outputs yet.\n\n--------------------------------------------------------------------------------\n1 fits failed with the following error:\nTraceback (most recent call last):\n  File \"/usr/local/lib/python3.11/dist-packages/sklearn/model_selection/_validation.py\", line 895, in _fit_and_score\n    estimator.fit(X_train, y_train, **fit_params)\n  File \"/usr/local/lib/python3.11/dist-packages/scikeras/wrappers.py\", line 1491, in fit\n    super().fit(X=X, y=y, sample_weight=sample_weight, **kwargs)\n  File \"/usr/local/lib/python3.11/dist-packages/scikeras/wrappers.py\", line 760, in fit\n    self._fit(\n  File \"/usr/local/lib/python3.11/dist-packages/scikeras/wrappers.py\", line 926, in _fit\n    self._check_model_compatibility(y)\n  File \"/usr/local/lib/python3.11/dist-packages/scikeras/wrappers.py\", line 549, in _check_model_compatibility\n    if self.n_outputs_expected_ != len(self.model_.outputs):\n                                       ^^^^^^^^^^^^^^^^^^^\n  File \"/usr/local/lib/python3.11/dist-packages/keras/src/models/sequential.py\", line 308, in outputs\n    raise AttributeError(\nAttributeError: Sequential model 'sequential_70' has no defined outputs yet.\n\n--------------------------------------------------------------------------------\n1 fits failed with the following error:\nTraceback (most recent call last):\n  File \"/usr/local/lib/python3.11/dist-packages/sklearn/model_selection/_validation.py\", line 895, in _fit_and_score\n    estimator.fit(X_train, y_train, **fit_params)\n  File \"/usr/local/lib/python3.11/dist-packages/scikeras/wrappers.py\", line 1491, in fit\n    super().fit(X=X, y=y, sample_weight=sample_weight, **kwargs)\n  File \"/usr/local/lib/python3.11/dist-packages/scikeras/wrappers.py\", line 760, in fit\n    self._fit(\n  File \"/usr/local/lib/python3.11/dist-packages/scikeras/wrappers.py\", line 926, in _fit\n    self._check_model_compatibility(y)\n  File \"/usr/local/lib/python3.11/dist-packages/scikeras/wrappers.py\", line 549, in _check_model_compatibility\n    if self.n_outputs_expected_ != len(self.model_.outputs):\n                                       ^^^^^^^^^^^^^^^^^^^\n  File \"/usr/local/lib/python3.11/dist-packages/keras/src/models/sequential.py\", line 308, in outputs\n    raise AttributeError(\nAttributeError: Sequential model 'sequential_71' has no defined outputs yet.\n\n--------------------------------------------------------------------------------\n1 fits failed with the following error:\nTraceback (most recent call last):\n  File \"/usr/local/lib/python3.11/dist-packages/sklearn/model_selection/_validation.py\", line 895, in _fit_and_score\n    estimator.fit(X_train, y_train, **fit_params)\n  File \"/usr/local/lib/python3.11/dist-packages/scikeras/wrappers.py\", line 1491, in fit\n    super().fit(X=X, y=y, sample_weight=sample_weight, **kwargs)\n  File \"/usr/local/lib/python3.11/dist-packages/scikeras/wrappers.py\", line 760, in fit\n    self._fit(\n  File \"/usr/local/lib/python3.11/dist-packages/scikeras/wrappers.py\", line 926, in _fit\n    self._check_model_compatibility(y)\n  File \"/usr/local/lib/python3.11/dist-packages/scikeras/wrappers.py\", line 549, in _check_model_compatibility\n    if self.n_outputs_expected_ != len(self.model_.outputs):\n                                       ^^^^^^^^^^^^^^^^^^^\n  File \"/usr/local/lib/python3.11/dist-packages/keras/src/models/sequential.py\", line 308, in outputs\n    raise AttributeError(\nAttributeError: Sequential model 'sequential_72' has no defined outputs yet.\n\n--------------------------------------------------------------------------------\n1 fits failed with the following error:\nTraceback (most recent call last):\n  File \"/usr/local/lib/python3.11/dist-packages/sklearn/model_selection/_validation.py\", line 895, in _fit_and_score\n    estimator.fit(X_train, y_train, **fit_params)\n  File \"/usr/local/lib/python3.11/dist-packages/scikeras/wrappers.py\", line 1491, in fit\n    super().fit(X=X, y=y, sample_weight=sample_weight, **kwargs)\n  File \"/usr/local/lib/python3.11/dist-packages/scikeras/wrappers.py\", line 760, in fit\n    self._fit(\n  File \"/usr/local/lib/python3.11/dist-packages/scikeras/wrappers.py\", line 926, in _fit\n    self._check_model_compatibility(y)\n  File \"/usr/local/lib/python3.11/dist-packages/scikeras/wrappers.py\", line 549, in _check_model_compatibility\n    if self.n_outputs_expected_ != len(self.model_.outputs):\n                                       ^^^^^^^^^^^^^^^^^^^\n  File \"/usr/local/lib/python3.11/dist-packages/keras/src/models/sequential.py\", line 308, in outputs\n    raise AttributeError(\nAttributeError: Sequential model 'sequential_73' has no defined outputs yet.\n\n--------------------------------------------------------------------------------\n1 fits failed with the following error:\nTraceback (most recent call last):\n  File \"/usr/local/lib/python3.11/dist-packages/sklearn/model_selection/_validation.py\", line 895, in _fit_and_score\n    estimator.fit(X_train, y_train, **fit_params)\n  File \"/usr/local/lib/python3.11/dist-packages/scikeras/wrappers.py\", line 1491, in fit\n    super().fit(X=X, y=y, sample_weight=sample_weight, **kwargs)\n  File \"/usr/local/lib/python3.11/dist-packages/scikeras/wrappers.py\", line 760, in fit\n    self._fit(\n  File \"/usr/local/lib/python3.11/dist-packages/scikeras/wrappers.py\", line 926, in _fit\n    self._check_model_compatibility(y)\n  File \"/usr/local/lib/python3.11/dist-packages/scikeras/wrappers.py\", line 549, in _check_model_compatibility\n    if self.n_outputs_expected_ != len(self.model_.outputs):\n                                       ^^^^^^^^^^^^^^^^^^^\n  File \"/usr/local/lib/python3.11/dist-packages/keras/src/models/sequential.py\", line 308, in outputs\n    raise AttributeError(\nAttributeError: Sequential model 'sequential_74' has no defined outputs yet.\n\n--------------------------------------------------------------------------------\n1 fits failed with the following error:\nTraceback (most recent call last):\n  File \"/usr/local/lib/python3.11/dist-packages/sklearn/model_selection/_validation.py\", line 895, in _fit_and_score\n    estimator.fit(X_train, y_train, **fit_params)\n  File \"/usr/local/lib/python3.11/dist-packages/scikeras/wrappers.py\", line 1491, in fit\n    super().fit(X=X, y=y, sample_weight=sample_weight, **kwargs)\n  File \"/usr/local/lib/python3.11/dist-packages/scikeras/wrappers.py\", line 760, in fit\n    self._fit(\n  File \"/usr/local/lib/python3.11/dist-packages/scikeras/wrappers.py\", line 926, in _fit\n    self._check_model_compatibility(y)\n  File \"/usr/local/lib/python3.11/dist-packages/scikeras/wrappers.py\", line 549, in _check_model_compatibility\n    if self.n_outputs_expected_ != len(self.model_.outputs):\n                                       ^^^^^^^^^^^^^^^^^^^\n  File \"/usr/local/lib/python3.11/dist-packages/keras/src/models/sequential.py\", line 308, in outputs\n    raise AttributeError(\nAttributeError: Sequential model 'sequential_75' has no defined outputs yet.\n\n--------------------------------------------------------------------------------\n1 fits failed with the following error:\nTraceback (most recent call last):\n  File \"/usr/local/lib/python3.11/dist-packages/sklearn/model_selection/_validation.py\", line 895, in _fit_and_score\n    estimator.fit(X_train, y_train, **fit_params)\n  File \"/usr/local/lib/python3.11/dist-packages/scikeras/wrappers.py\", line 1491, in fit\n    super().fit(X=X, y=y, sample_weight=sample_weight, **kwargs)\n  File \"/usr/local/lib/python3.11/dist-packages/scikeras/wrappers.py\", line 760, in fit\n    self._fit(\n  File \"/usr/local/lib/python3.11/dist-packages/scikeras/wrappers.py\", line 926, in _fit\n    self._check_model_compatibility(y)\n  File \"/usr/local/lib/python3.11/dist-packages/scikeras/wrappers.py\", line 549, in _check_model_compatibility\n    if self.n_outputs_expected_ != len(self.model_.outputs):\n                                       ^^^^^^^^^^^^^^^^^^^\n  File \"/usr/local/lib/python3.11/dist-packages/keras/src/models/sequential.py\", line 308, in outputs\n    raise AttributeError(\nAttributeError: Sequential model 'sequential_76' has no defined outputs yet.\n\n--------------------------------------------------------------------------------\n1 fits failed with the following error:\nTraceback (most recent call last):\n  File \"/usr/local/lib/python3.11/dist-packages/sklearn/model_selection/_validation.py\", line 895, in _fit_and_score\n    estimator.fit(X_train, y_train, **fit_params)\n  File \"/usr/local/lib/python3.11/dist-packages/scikeras/wrappers.py\", line 1491, in fit\n    super().fit(X=X, y=y, sample_weight=sample_weight, **kwargs)\n  File \"/usr/local/lib/python3.11/dist-packages/scikeras/wrappers.py\", line 760, in fit\n    self._fit(\n  File \"/usr/local/lib/python3.11/dist-packages/scikeras/wrappers.py\", line 926, in _fit\n    self._check_model_compatibility(y)\n  File \"/usr/local/lib/python3.11/dist-packages/scikeras/wrappers.py\", line 549, in _check_model_compatibility\n    if self.n_outputs_expected_ != len(self.model_.outputs):\n                                       ^^^^^^^^^^^^^^^^^^^\n  File \"/usr/local/lib/python3.11/dist-packages/keras/src/models/sequential.py\", line 308, in outputs\n    raise AttributeError(\nAttributeError: Sequential model 'sequential_77' has no defined outputs yet.\n\n--------------------------------------------------------------------------------\n1 fits failed with the following error:\nTraceback (most recent call last):\n  File \"/usr/local/lib/python3.11/dist-packages/sklearn/model_selection/_validation.py\", line 895, in _fit_and_score\n    estimator.fit(X_train, y_train, **fit_params)\n  File \"/usr/local/lib/python3.11/dist-packages/scikeras/wrappers.py\", line 1491, in fit\n    super().fit(X=X, y=y, sample_weight=sample_weight, **kwargs)\n  File \"/usr/local/lib/python3.11/dist-packages/scikeras/wrappers.py\", line 760, in fit\n    self._fit(\n  File \"/usr/local/lib/python3.11/dist-packages/scikeras/wrappers.py\", line 926, in _fit\n    self._check_model_compatibility(y)\n  File \"/usr/local/lib/python3.11/dist-packages/scikeras/wrappers.py\", line 549, in _check_model_compatibility\n    if self.n_outputs_expected_ != len(self.model_.outputs):\n                                       ^^^^^^^^^^^^^^^^^^^\n  File \"/usr/local/lib/python3.11/dist-packages/keras/src/models/sequential.py\", line 308, in outputs\n    raise AttributeError(\nAttributeError: Sequential model 'sequential_78' has no defined outputs yet.\n\n--------------------------------------------------------------------------------\n1 fits failed with the following error:\nTraceback (most recent call last):\n  File \"/usr/local/lib/python3.11/dist-packages/sklearn/model_selection/_validation.py\", line 895, in _fit_and_score\n    estimator.fit(X_train, y_train, **fit_params)\n  File \"/usr/local/lib/python3.11/dist-packages/scikeras/wrappers.py\", line 1491, in fit\n    super().fit(X=X, y=y, sample_weight=sample_weight, **kwargs)\n  File \"/usr/local/lib/python3.11/dist-packages/scikeras/wrappers.py\", line 760, in fit\n    self._fit(\n  File \"/usr/local/lib/python3.11/dist-packages/scikeras/wrappers.py\", line 926, in _fit\n    self._check_model_compatibility(y)\n  File \"/usr/local/lib/python3.11/dist-packages/scikeras/wrappers.py\", line 549, in _check_model_compatibility\n    if self.n_outputs_expected_ != len(self.model_.outputs):\n                                       ^^^^^^^^^^^^^^^^^^^\n  File \"/usr/local/lib/python3.11/dist-packages/keras/src/models/sequential.py\", line 308, in outputs\n    raise AttributeError(\nAttributeError: Sequential model 'sequential_79' has no defined outputs yet.\n\n--------------------------------------------------------------------------------\n1 fits failed with the following error:\nTraceback (most recent call last):\n  File \"/usr/local/lib/python3.11/dist-packages/sklearn/model_selection/_validation.py\", line 895, in _fit_and_score\n    estimator.fit(X_train, y_train, **fit_params)\n  File \"/usr/local/lib/python3.11/dist-packages/scikeras/wrappers.py\", line 1491, in fit\n    super().fit(X=X, y=y, sample_weight=sample_weight, **kwargs)\n  File \"/usr/local/lib/python3.11/dist-packages/scikeras/wrappers.py\", line 760, in fit\n    self._fit(\n  File \"/usr/local/lib/python3.11/dist-packages/scikeras/wrappers.py\", line 926, in _fit\n    self._check_model_compatibility(y)\n  File \"/usr/local/lib/python3.11/dist-packages/scikeras/wrappers.py\", line 549, in _check_model_compatibility\n    if self.n_outputs_expected_ != len(self.model_.outputs):\n                                       ^^^^^^^^^^^^^^^^^^^\n  File \"/usr/local/lib/python3.11/dist-packages/keras/src/models/sequential.py\", line 308, in outputs\n    raise AttributeError(\nAttributeError: Sequential model 'sequential_80' has no defined outputs yet.\n\n--------------------------------------------------------------------------------\n1 fits failed with the following error:\nTraceback (most recent call last):\n  File \"/usr/local/lib/python3.11/dist-packages/sklearn/model_selection/_validation.py\", line 895, in _fit_and_score\n    estimator.fit(X_train, y_train, **fit_params)\n  File \"/usr/local/lib/python3.11/dist-packages/scikeras/wrappers.py\", line 1491, in fit\n    super().fit(X=X, y=y, sample_weight=sample_weight, **kwargs)\n  File \"/usr/local/lib/python3.11/dist-packages/scikeras/wrappers.py\", line 760, in fit\n    self._fit(\n  File \"/usr/local/lib/python3.11/dist-packages/scikeras/wrappers.py\", line 926, in _fit\n    self._check_model_compatibility(y)\n  File \"/usr/local/lib/python3.11/dist-packages/scikeras/wrappers.py\", line 549, in _check_model_compatibility\n    if self.n_outputs_expected_ != len(self.model_.outputs):\n                                       ^^^^^^^^^^^^^^^^^^^\n  File \"/usr/local/lib/python3.11/dist-packages/keras/src/models/sequential.py\", line 308, in outputs\n    raise AttributeError(\nAttributeError: Sequential model 'sequential_81' has no defined outputs yet.\n\n--------------------------------------------------------------------------------\n1 fits failed with the following error:\nTraceback (most recent call last):\n  File \"/usr/local/lib/python3.11/dist-packages/sklearn/model_selection/_validation.py\", line 895, in _fit_and_score\n    estimator.fit(X_train, y_train, **fit_params)\n  File \"/usr/local/lib/python3.11/dist-packages/scikeras/wrappers.py\", line 1491, in fit\n    super().fit(X=X, y=y, sample_weight=sample_weight, **kwargs)\n  File \"/usr/local/lib/python3.11/dist-packages/scikeras/wrappers.py\", line 760, in fit\n    self._fit(\n  File \"/usr/local/lib/python3.11/dist-packages/scikeras/wrappers.py\", line 926, in _fit\n    self._check_model_compatibility(y)\n  File \"/usr/local/lib/python3.11/dist-packages/scikeras/wrappers.py\", line 549, in _check_model_compatibility\n    if self.n_outputs_expected_ != len(self.model_.outputs):\n                                       ^^^^^^^^^^^^^^^^^^^\n  File \"/usr/local/lib/python3.11/dist-packages/keras/src/models/sequential.py\", line 308, in outputs\n    raise AttributeError(\nAttributeError: Sequential model 'sequential_82' has no defined outputs yet.\n\n--------------------------------------------------------------------------------\n1 fits failed with the following error:\nTraceback (most recent call last):\n  File \"/usr/local/lib/python3.11/dist-packages/sklearn/model_selection/_validation.py\", line 895, in _fit_and_score\n    estimator.fit(X_train, y_train, **fit_params)\n  File \"/usr/local/lib/python3.11/dist-packages/scikeras/wrappers.py\", line 1491, in fit\n    super().fit(X=X, y=y, sample_weight=sample_weight, **kwargs)\n  File \"/usr/local/lib/python3.11/dist-packages/scikeras/wrappers.py\", line 760, in fit\n    self._fit(\n  File \"/usr/local/lib/python3.11/dist-packages/scikeras/wrappers.py\", line 926, in _fit\n    self._check_model_compatibility(y)\n  File \"/usr/local/lib/python3.11/dist-packages/scikeras/wrappers.py\", line 549, in _check_model_compatibility\n    if self.n_outputs_expected_ != len(self.model_.outputs):\n                                       ^^^^^^^^^^^^^^^^^^^\n  File \"/usr/local/lib/python3.11/dist-packages/keras/src/models/sequential.py\", line 308, in outputs\n    raise AttributeError(\nAttributeError: Sequential model 'sequential_83' has no defined outputs yet.\n\n--------------------------------------------------------------------------------\n1 fits failed with the following error:\nTraceback (most recent call last):\n  File \"/usr/local/lib/python3.11/dist-packages/sklearn/model_selection/_validation.py\", line 895, in _fit_and_score\n    estimator.fit(X_train, y_train, **fit_params)\n  File \"/usr/local/lib/python3.11/dist-packages/scikeras/wrappers.py\", line 1491, in fit\n    super().fit(X=X, y=y, sample_weight=sample_weight, **kwargs)\n  File \"/usr/local/lib/python3.11/dist-packages/scikeras/wrappers.py\", line 760, in fit\n    self._fit(\n  File \"/usr/local/lib/python3.11/dist-packages/scikeras/wrappers.py\", line 926, in _fit\n    self._check_model_compatibility(y)\n  File \"/usr/local/lib/python3.11/dist-packages/scikeras/wrappers.py\", line 549, in _check_model_compatibility\n    if self.n_outputs_expected_ != len(self.model_.outputs):\n                                       ^^^^^^^^^^^^^^^^^^^\n  File \"/usr/local/lib/python3.11/dist-packages/keras/src/models/sequential.py\", line 308, in outputs\n    raise AttributeError(\nAttributeError: Sequential model 'sequential_84' has no defined outputs yet.\n\n--------------------------------------------------------------------------------\n1 fits failed with the following error:\nTraceback (most recent call last):\n  File \"/usr/local/lib/python3.11/dist-packages/sklearn/model_selection/_validation.py\", line 895, in _fit_and_score\n    estimator.fit(X_train, y_train, **fit_params)\n  File \"/usr/local/lib/python3.11/dist-packages/scikeras/wrappers.py\", line 1491, in fit\n    super().fit(X=X, y=y, sample_weight=sample_weight, **kwargs)\n  File \"/usr/local/lib/python3.11/dist-packages/scikeras/wrappers.py\", line 760, in fit\n    self._fit(\n  File \"/usr/local/lib/python3.11/dist-packages/scikeras/wrappers.py\", line 926, in _fit\n    self._check_model_compatibility(y)\n  File \"/usr/local/lib/python3.11/dist-packages/scikeras/wrappers.py\", line 549, in _check_model_compatibility\n    if self.n_outputs_expected_ != len(self.model_.outputs):\n                                       ^^^^^^^^^^^^^^^^^^^\n  File \"/usr/local/lib/python3.11/dist-packages/keras/src/models/sequential.py\", line 308, in outputs\n    raise AttributeError(\nAttributeError: Sequential model 'sequential_85' has no defined outputs yet.\n\n--------------------------------------------------------------------------------\n1 fits failed with the following error:\nTraceback (most recent call last):\n  File \"/usr/local/lib/python3.11/dist-packages/sklearn/model_selection/_validation.py\", line 895, in _fit_and_score\n    estimator.fit(X_train, y_train, **fit_params)\n  File \"/usr/local/lib/python3.11/dist-packages/scikeras/wrappers.py\", line 1491, in fit\n    super().fit(X=X, y=y, sample_weight=sample_weight, **kwargs)\n  File \"/usr/local/lib/python3.11/dist-packages/scikeras/wrappers.py\", line 760, in fit\n    self._fit(\n  File \"/usr/local/lib/python3.11/dist-packages/scikeras/wrappers.py\", line 926, in _fit\n    self._check_model_compatibility(y)\n  File \"/usr/local/lib/python3.11/dist-packages/scikeras/wrappers.py\", line 549, in _check_model_compatibility\n    if self.n_outputs_expected_ != len(self.model_.outputs):\n                                       ^^^^^^^^^^^^^^^^^^^\n  File \"/usr/local/lib/python3.11/dist-packages/keras/src/models/sequential.py\", line 308, in outputs\n    raise AttributeError(\nAttributeError: Sequential model 'sequential_86' has no defined outputs yet.\n\n--------------------------------------------------------------------------------\n1 fits failed with the following error:\nTraceback (most recent call last):\n  File \"/usr/local/lib/python3.11/dist-packages/sklearn/model_selection/_validation.py\", line 895, in _fit_and_score\n    estimator.fit(X_train, y_train, **fit_params)\n  File \"/usr/local/lib/python3.11/dist-packages/scikeras/wrappers.py\", line 1491, in fit\n    super().fit(X=X, y=y, sample_weight=sample_weight, **kwargs)\n  File \"/usr/local/lib/python3.11/dist-packages/scikeras/wrappers.py\", line 760, in fit\n    self._fit(\n  File \"/usr/local/lib/python3.11/dist-packages/scikeras/wrappers.py\", line 926, in _fit\n    self._check_model_compatibility(y)\n  File \"/usr/local/lib/python3.11/dist-packages/scikeras/wrappers.py\", line 549, in _check_model_compatibility\n    if self.n_outputs_expected_ != len(self.model_.outputs):\n                                       ^^^^^^^^^^^^^^^^^^^\n  File \"/usr/local/lib/python3.11/dist-packages/keras/src/models/sequential.py\", line 308, in outputs\n    raise AttributeError(\nAttributeError: Sequential model 'sequential_87' has no defined outputs yet.\n\n--------------------------------------------------------------------------------\n1 fits failed with the following error:\nTraceback (most recent call last):\n  File \"/usr/local/lib/python3.11/dist-packages/sklearn/model_selection/_validation.py\", line 895, in _fit_and_score\n    estimator.fit(X_train, y_train, **fit_params)\n  File \"/usr/local/lib/python3.11/dist-packages/scikeras/wrappers.py\", line 1491, in fit\n    super().fit(X=X, y=y, sample_weight=sample_weight, **kwargs)\n  File \"/usr/local/lib/python3.11/dist-packages/scikeras/wrappers.py\", line 760, in fit\n    self._fit(\n  File \"/usr/local/lib/python3.11/dist-packages/scikeras/wrappers.py\", line 926, in _fit\n    self._check_model_compatibility(y)\n  File \"/usr/local/lib/python3.11/dist-packages/scikeras/wrappers.py\", line 549, in _check_model_compatibility\n    if self.n_outputs_expected_ != len(self.model_.outputs):\n                                       ^^^^^^^^^^^^^^^^^^^\n  File \"/usr/local/lib/python3.11/dist-packages/keras/src/models/sequential.py\", line 308, in outputs\n    raise AttributeError(\nAttributeError: Sequential model 'sequential_88' has no defined outputs yet.\n\n--------------------------------------------------------------------------------\n1 fits failed with the following error:\nTraceback (most recent call last):\n  File \"/usr/local/lib/python3.11/dist-packages/sklearn/model_selection/_validation.py\", line 895, in _fit_and_score\n    estimator.fit(X_train, y_train, **fit_params)\n  File \"/usr/local/lib/python3.11/dist-packages/scikeras/wrappers.py\", line 1491, in fit\n    super().fit(X=X, y=y, sample_weight=sample_weight, **kwargs)\n  File \"/usr/local/lib/python3.11/dist-packages/scikeras/wrappers.py\", line 760, in fit\n    self._fit(\n  File \"/usr/local/lib/python3.11/dist-packages/scikeras/wrappers.py\", line 926, in _fit\n    self._check_model_compatibility(y)\n  File \"/usr/local/lib/python3.11/dist-packages/scikeras/wrappers.py\", line 549, in _check_model_compatibility\n    if self.n_outputs_expected_ != len(self.model_.outputs):\n                                       ^^^^^^^^^^^^^^^^^^^\n  File \"/usr/local/lib/python3.11/dist-packages/keras/src/models/sequential.py\", line 308, in outputs\n    raise AttributeError(\nAttributeError: Sequential model 'sequential_89' has no defined outputs yet.\n\n--------------------------------------------------------------------------------\n1 fits failed with the following error:\nTraceback (most recent call last):\n  File \"/usr/local/lib/python3.11/dist-packages/sklearn/model_selection/_validation.py\", line 895, in _fit_and_score\n    estimator.fit(X_train, y_train, **fit_params)\n  File \"/usr/local/lib/python3.11/dist-packages/scikeras/wrappers.py\", line 1491, in fit\n    super().fit(X=X, y=y, sample_weight=sample_weight, **kwargs)\n  File \"/usr/local/lib/python3.11/dist-packages/scikeras/wrappers.py\", line 760, in fit\n    self._fit(\n  File \"/usr/local/lib/python3.11/dist-packages/scikeras/wrappers.py\", line 926, in _fit\n    self._check_model_compatibility(y)\n  File \"/usr/local/lib/python3.11/dist-packages/scikeras/wrappers.py\", line 549, in _check_model_compatibility\n    if self.n_outputs_expected_ != len(self.model_.outputs):\n                                       ^^^^^^^^^^^^^^^^^^^\n  File \"/usr/local/lib/python3.11/dist-packages/keras/src/models/sequential.py\", line 308, in outputs\n    raise AttributeError(\nAttributeError: Sequential model 'sequential_90' has no defined outputs yet.\n\n--------------------------------------------------------------------------------\n1 fits failed with the following error:\nTraceback (most recent call last):\n  File \"/usr/local/lib/python3.11/dist-packages/sklearn/model_selection/_validation.py\", line 895, in _fit_and_score\n    estimator.fit(X_train, y_train, **fit_params)\n  File \"/usr/local/lib/python3.11/dist-packages/scikeras/wrappers.py\", line 1491, in fit\n    super().fit(X=X, y=y, sample_weight=sample_weight, **kwargs)\n  File \"/usr/local/lib/python3.11/dist-packages/scikeras/wrappers.py\", line 760, in fit\n    self._fit(\n  File \"/usr/local/lib/python3.11/dist-packages/scikeras/wrappers.py\", line 926, in _fit\n    self._check_model_compatibility(y)\n  File \"/usr/local/lib/python3.11/dist-packages/scikeras/wrappers.py\", line 549, in _check_model_compatibility\n    if self.n_outputs_expected_ != len(self.model_.outputs):\n                                       ^^^^^^^^^^^^^^^^^^^\n  File \"/usr/local/lib/python3.11/dist-packages/keras/src/models/sequential.py\", line 308, in outputs\n    raise AttributeError(\nAttributeError: Sequential model 'sequential_91' has no defined outputs yet.\n\n--------------------------------------------------------------------------------\n1 fits failed with the following error:\nTraceback (most recent call last):\n  File \"/usr/local/lib/python3.11/dist-packages/sklearn/model_selection/_validation.py\", line 895, in _fit_and_score\n    estimator.fit(X_train, y_train, **fit_params)\n  File \"/usr/local/lib/python3.11/dist-packages/scikeras/wrappers.py\", line 1491, in fit\n    super().fit(X=X, y=y, sample_weight=sample_weight, **kwargs)\n  File \"/usr/local/lib/python3.11/dist-packages/scikeras/wrappers.py\", line 760, in fit\n    self._fit(\n  File \"/usr/local/lib/python3.11/dist-packages/scikeras/wrappers.py\", line 926, in _fit\n    self._check_model_compatibility(y)\n  File \"/usr/local/lib/python3.11/dist-packages/scikeras/wrappers.py\", line 549, in _check_model_compatibility\n    if self.n_outputs_expected_ != len(self.model_.outputs):\n                                       ^^^^^^^^^^^^^^^^^^^\n  File \"/usr/local/lib/python3.11/dist-packages/keras/src/models/sequential.py\", line 308, in outputs\n    raise AttributeError(\nAttributeError: Sequential model 'sequential_92' has no defined outputs yet.\n\n--------------------------------------------------------------------------------\n1 fits failed with the following error:\nTraceback (most recent call last):\n  File \"/usr/local/lib/python3.11/dist-packages/sklearn/model_selection/_validation.py\", line 895, in _fit_and_score\n    estimator.fit(X_train, y_train, **fit_params)\n  File \"/usr/local/lib/python3.11/dist-packages/scikeras/wrappers.py\", line 1491, in fit\n    super().fit(X=X, y=y, sample_weight=sample_weight, **kwargs)\n  File \"/usr/local/lib/python3.11/dist-packages/scikeras/wrappers.py\", line 760, in fit\n    self._fit(\n  File \"/usr/local/lib/python3.11/dist-packages/scikeras/wrappers.py\", line 926, in _fit\n    self._check_model_compatibility(y)\n  File \"/usr/local/lib/python3.11/dist-packages/scikeras/wrappers.py\", line 549, in _check_model_compatibility\n    if self.n_outputs_expected_ != len(self.model_.outputs):\n                                       ^^^^^^^^^^^^^^^^^^^\n  File \"/usr/local/lib/python3.11/dist-packages/keras/src/models/sequential.py\", line 308, in outputs\n    raise AttributeError(\nAttributeError: Sequential model 'sequential_93' has no defined outputs yet.\n\n--------------------------------------------------------------------------------\n1 fits failed with the following error:\nTraceback (most recent call last):\n  File \"/usr/local/lib/python3.11/dist-packages/sklearn/model_selection/_validation.py\", line 895, in _fit_and_score\n    estimator.fit(X_train, y_train, **fit_params)\n  File \"/usr/local/lib/python3.11/dist-packages/scikeras/wrappers.py\", line 1491, in fit\n    super().fit(X=X, y=y, sample_weight=sample_weight, **kwargs)\n  File \"/usr/local/lib/python3.11/dist-packages/scikeras/wrappers.py\", line 760, in fit\n    self._fit(\n  File \"/usr/local/lib/python3.11/dist-packages/scikeras/wrappers.py\", line 926, in _fit\n    self._check_model_compatibility(y)\n  File \"/usr/local/lib/python3.11/dist-packages/scikeras/wrappers.py\", line 549, in _check_model_compatibility\n    if self.n_outputs_expected_ != len(self.model_.outputs):\n                                       ^^^^^^^^^^^^^^^^^^^\n  File \"/usr/local/lib/python3.11/dist-packages/keras/src/models/sequential.py\", line 308, in outputs\n    raise AttributeError(\nAttributeError: Sequential model 'sequential_94' has no defined outputs yet.\n\n--------------------------------------------------------------------------------\n1 fits failed with the following error:\nTraceback (most recent call last):\n  File \"/usr/local/lib/python3.11/dist-packages/sklearn/model_selection/_validation.py\", line 895, in _fit_and_score\n    estimator.fit(X_train, y_train, **fit_params)\n  File \"/usr/local/lib/python3.11/dist-packages/scikeras/wrappers.py\", line 1491, in fit\n    super().fit(X=X, y=y, sample_weight=sample_weight, **kwargs)\n  File \"/usr/local/lib/python3.11/dist-packages/scikeras/wrappers.py\", line 760, in fit\n    self._fit(\n  File \"/usr/local/lib/python3.11/dist-packages/scikeras/wrappers.py\", line 926, in _fit\n    self._check_model_compatibility(y)\n  File \"/usr/local/lib/python3.11/dist-packages/scikeras/wrappers.py\", line 549, in _check_model_compatibility\n    if self.n_outputs_expected_ != len(self.model_.outputs):\n                                       ^^^^^^^^^^^^^^^^^^^\n  File \"/usr/local/lib/python3.11/dist-packages/keras/src/models/sequential.py\", line 308, in outputs\n    raise AttributeError(\nAttributeError: Sequential model 'sequential_95' has no defined outputs yet.\n\n--------------------------------------------------------------------------------\n1 fits failed with the following error:\nTraceback (most recent call last):\n  File \"/usr/local/lib/python3.11/dist-packages/sklearn/model_selection/_validation.py\", line 895, in _fit_and_score\n    estimator.fit(X_train, y_train, **fit_params)\n  File \"/usr/local/lib/python3.11/dist-packages/scikeras/wrappers.py\", line 1491, in fit\n    super().fit(X=X, y=y, sample_weight=sample_weight, **kwargs)\n  File \"/usr/local/lib/python3.11/dist-packages/scikeras/wrappers.py\", line 760, in fit\n    self._fit(\n  File \"/usr/local/lib/python3.11/dist-packages/scikeras/wrappers.py\", line 926, in _fit\n    self._check_model_compatibility(y)\n  File \"/usr/local/lib/python3.11/dist-packages/scikeras/wrappers.py\", line 549, in _check_model_compatibility\n    if self.n_outputs_expected_ != len(self.model_.outputs):\n                                       ^^^^^^^^^^^^^^^^^^^\n  File \"/usr/local/lib/python3.11/dist-packages/keras/src/models/sequential.py\", line 308, in outputs\n    raise AttributeError(\nAttributeError: Sequential model 'sequential_96' has no defined outputs yet.\n\n--------------------------------------------------------------------------------\n1 fits failed with the following error:\nTraceback (most recent call last):\n  File \"/usr/local/lib/python3.11/dist-packages/sklearn/model_selection/_validation.py\", line 895, in _fit_and_score\n    estimator.fit(X_train, y_train, **fit_params)\n  File \"/usr/local/lib/python3.11/dist-packages/scikeras/wrappers.py\", line 1491, in fit\n    super().fit(X=X, y=y, sample_weight=sample_weight, **kwargs)\n  File \"/usr/local/lib/python3.11/dist-packages/scikeras/wrappers.py\", line 760, in fit\n    self._fit(\n  File \"/usr/local/lib/python3.11/dist-packages/scikeras/wrappers.py\", line 926, in _fit\n    self._check_model_compatibility(y)\n  File \"/usr/local/lib/python3.11/dist-packages/scikeras/wrappers.py\", line 549, in _check_model_compatibility\n    if self.n_outputs_expected_ != len(self.model_.outputs):\n                                       ^^^^^^^^^^^^^^^^^^^\n  File \"/usr/local/lib/python3.11/dist-packages/keras/src/models/sequential.py\", line 308, in outputs\n    raise AttributeError(\nAttributeError: Sequential model 'sequential_97' has no defined outputs yet.\n",
          "traceback": [
            "\u001b[0;31m---------------------------------------------------------------------------\u001b[0m",
            "\u001b[0;31mValueError\u001b[0m                                Traceback (most recent call last)",
            "\u001b[0;32m<ipython-input-25-57a88dfec415>\u001b[0m in \u001b[0;36m<cell line: 0>\u001b[0;34m()\u001b[0m\n\u001b[1;32m     93\u001b[0m \u001b[0;31m# -------------------------------\u001b[0m\u001b[0;34m\u001b[0m\u001b[0;34m\u001b[0m\u001b[0m\n\u001b[1;32m     94\u001b[0m \u001b[0;34m\u001b[0m\u001b[0m\n\u001b[0;32m---> 95\u001b[0;31m \u001b[0mgrid_result\u001b[0m \u001b[0;34m=\u001b[0m \u001b[0mgrid\u001b[0m\u001b[0;34m.\u001b[0m\u001b[0mfit\u001b[0m\u001b[0;34m(\u001b[0m\u001b[0mX_train\u001b[0m\u001b[0;34m,\u001b[0m \u001b[0mY_train\u001b[0m\u001b[0;34m)\u001b[0m\u001b[0;34m\u001b[0m\u001b[0;34m\u001b[0m\u001b[0m\n\u001b[0m\u001b[1;32m     96\u001b[0m \u001b[0;34m\u001b[0m\u001b[0m\n\u001b[1;32m     97\u001b[0m \u001b[0;31m# -------------------------------\u001b[0m\u001b[0;34m\u001b[0m\u001b[0;34m\u001b[0m\u001b[0m\n",
            "\u001b[0;32m/usr/local/lib/python3.11/dist-packages/sklearn/base.py\u001b[0m in \u001b[0;36mwrapper\u001b[0;34m(estimator, *args, **kwargs)\u001b[0m\n\u001b[1;32m   1472\u001b[0m                 )\n\u001b[1;32m   1473\u001b[0m             ):\n\u001b[0;32m-> 1474\u001b[0;31m                 \u001b[0;32mreturn\u001b[0m \u001b[0mfit_method\u001b[0m\u001b[0;34m(\u001b[0m\u001b[0mestimator\u001b[0m\u001b[0;34m,\u001b[0m \u001b[0;34m*\u001b[0m\u001b[0margs\u001b[0m\u001b[0;34m,\u001b[0m \u001b[0;34m**\u001b[0m\u001b[0mkwargs\u001b[0m\u001b[0;34m)\u001b[0m\u001b[0;34m\u001b[0m\u001b[0;34m\u001b[0m\u001b[0m\n\u001b[0m\u001b[1;32m   1475\u001b[0m \u001b[0;34m\u001b[0m\u001b[0m\n\u001b[1;32m   1476\u001b[0m         \u001b[0;32mreturn\u001b[0m \u001b[0mwrapper\u001b[0m\u001b[0;34m\u001b[0m\u001b[0;34m\u001b[0m\u001b[0m\n",
            "\u001b[0;32m/usr/local/lib/python3.11/dist-packages/sklearn/model_selection/_search.py\u001b[0m in \u001b[0;36mfit\u001b[0;34m(self, X, y, **params)\u001b[0m\n\u001b[1;32m    968\u001b[0m                 \u001b[0;32mreturn\u001b[0m \u001b[0mresults\u001b[0m\u001b[0;34m\u001b[0m\u001b[0;34m\u001b[0m\u001b[0m\n\u001b[1;32m    969\u001b[0m \u001b[0;34m\u001b[0m\u001b[0m\n\u001b[0;32m--> 970\u001b[0;31m             \u001b[0mself\u001b[0m\u001b[0;34m.\u001b[0m\u001b[0m_run_search\u001b[0m\u001b[0;34m(\u001b[0m\u001b[0mevaluate_candidates\u001b[0m\u001b[0;34m)\u001b[0m\u001b[0;34m\u001b[0m\u001b[0;34m\u001b[0m\u001b[0m\n\u001b[0m\u001b[1;32m    971\u001b[0m \u001b[0;34m\u001b[0m\u001b[0m\n\u001b[1;32m    972\u001b[0m             \u001b[0;31m# multimetric is determined here because in the case of a callable\u001b[0m\u001b[0;34m\u001b[0m\u001b[0;34m\u001b[0m\u001b[0m\n",
            "\u001b[0;32m/usr/local/lib/python3.11/dist-packages/sklearn/model_selection/_search.py\u001b[0m in \u001b[0;36m_run_search\u001b[0;34m(self, evaluate_candidates)\u001b[0m\n\u001b[1;32m   1525\u001b[0m     \u001b[0;32mdef\u001b[0m \u001b[0m_run_search\u001b[0m\u001b[0;34m(\u001b[0m\u001b[0mself\u001b[0m\u001b[0;34m,\u001b[0m \u001b[0mevaluate_candidates\u001b[0m\u001b[0;34m)\u001b[0m\u001b[0;34m:\u001b[0m\u001b[0;34m\u001b[0m\u001b[0;34m\u001b[0m\u001b[0m\n\u001b[1;32m   1526\u001b[0m         \u001b[0;34m\"\"\"Search all candidates in param_grid\"\"\"\u001b[0m\u001b[0;34m\u001b[0m\u001b[0;34m\u001b[0m\u001b[0m\n\u001b[0;32m-> 1527\u001b[0;31m         \u001b[0mevaluate_candidates\u001b[0m\u001b[0;34m(\u001b[0m\u001b[0mParameterGrid\u001b[0m\u001b[0;34m(\u001b[0m\u001b[0mself\u001b[0m\u001b[0;34m.\u001b[0m\u001b[0mparam_grid\u001b[0m\u001b[0;34m)\u001b[0m\u001b[0;34m)\u001b[0m\u001b[0;34m\u001b[0m\u001b[0;34m\u001b[0m\u001b[0m\n\u001b[0m\u001b[1;32m   1528\u001b[0m \u001b[0;34m\u001b[0m\u001b[0m\n\u001b[1;32m   1529\u001b[0m \u001b[0;34m\u001b[0m\u001b[0m\n",
            "\u001b[0;32m/usr/local/lib/python3.11/dist-packages/sklearn/model_selection/_search.py\u001b[0m in \u001b[0;36mevaluate_candidates\u001b[0;34m(candidate_params, cv, more_results)\u001b[0m\n\u001b[1;32m    945\u001b[0m                     )\n\u001b[1;32m    946\u001b[0m \u001b[0;34m\u001b[0m\u001b[0m\n\u001b[0;32m--> 947\u001b[0;31m                 \u001b[0m_warn_or_raise_about_fit_failures\u001b[0m\u001b[0;34m(\u001b[0m\u001b[0mout\u001b[0m\u001b[0;34m,\u001b[0m \u001b[0mself\u001b[0m\u001b[0;34m.\u001b[0m\u001b[0merror_score\u001b[0m\u001b[0;34m)\u001b[0m\u001b[0;34m\u001b[0m\u001b[0;34m\u001b[0m\u001b[0m\n\u001b[0m\u001b[1;32m    948\u001b[0m \u001b[0;34m\u001b[0m\u001b[0m\n\u001b[1;32m    949\u001b[0m                 \u001b[0;31m# For callable self.scoring, the return type is only know after\u001b[0m\u001b[0;34m\u001b[0m\u001b[0;34m\u001b[0m\u001b[0m\n",
            "\u001b[0;32m/usr/local/lib/python3.11/dist-packages/sklearn/model_selection/_validation.py\u001b[0m in \u001b[0;36m_warn_or_raise_about_fit_failures\u001b[0;34m(results, error_score)\u001b[0m\n\u001b[1;32m    534\u001b[0m                 \u001b[0;34mf\"Below are more details about the failures:\\n{fit_errors_summary}\"\u001b[0m\u001b[0;34m\u001b[0m\u001b[0;34m\u001b[0m\u001b[0m\n\u001b[1;32m    535\u001b[0m             )\n\u001b[0;32m--> 536\u001b[0;31m             \u001b[0;32mraise\u001b[0m \u001b[0mValueError\u001b[0m\u001b[0;34m(\u001b[0m\u001b[0mall_fits_failed_message\u001b[0m\u001b[0;34m)\u001b[0m\u001b[0;34m\u001b[0m\u001b[0;34m\u001b[0m\u001b[0m\n\u001b[0m\u001b[1;32m    537\u001b[0m \u001b[0;34m\u001b[0m\u001b[0m\n\u001b[1;32m    538\u001b[0m         \u001b[0;32melse\u001b[0m\u001b[0;34m:\u001b[0m\u001b[0;34m\u001b[0m\u001b[0;34m\u001b[0m\u001b[0m\n",
            "\u001b[0;31mValueError\u001b[0m: \nAll the 48 fits failed.\nIt is very likely that your model is misconfigured.\nYou can try to debug the error by setting error_score='raise'.\n\nBelow are more details about the failures:\n--------------------------------------------------------------------------------\n1 fits failed with the following error:\nTraceback (most recent call last):\n  File \"/usr/local/lib/python3.11/dist-packages/sklearn/model_selection/_validation.py\", line 895, in _fit_and_score\n    estimator.fit(X_train, y_train, **fit_params)\n  File \"/usr/local/lib/python3.11/dist-packages/scikeras/wrappers.py\", line 1491, in fit\n    super().fit(X=X, y=y, sample_weight=sample_weight, **kwargs)\n  File \"/usr/local/lib/python3.11/dist-packages/scikeras/wrappers.py\", line 760, in fit\n    self._fit(\n  File \"/usr/local/lib/python3.11/dist-packages/scikeras/wrappers.py\", line 926, in _fit\n    self._check_model_compatibility(y)\n  File \"/usr/local/lib/python3.11/dist-packages/scikeras/wrappers.py\", line 549, in _check_model_compatibility\n    if self.n_outputs_expected_ != len(self.model_.outputs):\n                                       ^^^^^^^^^^^^^^^^^^^\n  File \"/usr/local/lib/python3.11/dist-packages/keras/src/models/sequential.py\", line 308, in outputs\n    raise AttributeError(\nAttributeError: Sequential model 'sequential_50' has no defined outputs yet.\n\n--------------------------------------------------------------------------------\n1 fits failed with the following error:\nTraceback (most recent call last):\n  File \"/usr/local/lib/python3.11/dist-packages/sklearn/model_selection/_validation.py\", line 895, in _fit_and_score\n    estimator.fit(X_train, y_train, **fit_params)\n  File \"/usr/local/lib/python3.11/dist-packages/scikeras/wrappers.py\", line 1491, in fit\n    super().fit(X=X, y=y, sample_weight=sample_weight, **kwargs)\n  File \"/usr/local/lib/python3.11/dist-packages/scikeras/wrappers.py\", line 760, in fit\n    self._fit(\n  File \"/usr/local/lib/python3.11/dist-packages/scikeras/wrappers.py\", line 926, in _fit\n    self._check_model_compatibility(y)\n  File \"/usr/local/lib/python3.11/dist-packages/scikeras/wrappers.py\", line 549, in _check_model_compatibility\n    if self.n_outputs_expected_ != len(self.model_.outputs):\n                                       ^^^^^^^^^^^^^^^^^^^\n  File \"/usr/local/lib/python3.11/dist-packages/keras/src/models/sequential.py\", line 308, in outputs\n    raise AttributeError(\nAttributeError: Sequential model 'sequential_51' has no defined outputs yet.\n\n--------------------------------------------------------------------------------\n1 fits failed with the following error:\nTraceback (most recent call last):\n  File \"/usr/local/lib/python3.11/dist-packages/sklearn/model_selection/_validation.py\", line 895, in _fit_and_score\n    estimator.fit(X_train, y_train, **fit_params)\n  File \"/usr/local/lib/python3.11/dist-packages/scikeras/wrappers.py\", line 1491, in fit\n    super().fit(X=X, y=y, sample_weight=sample_weight, **kwargs)\n  File \"/usr/local/lib/python3.11/dist-packages/scikeras/wrappers.py\", line 760, in fit\n    self._fit(\n  File \"/usr/local/lib/python3.11/dist-packages/scikeras/wrappers.py\", line 926, in _fit\n    self._check_model_compatibility(y)\n  File \"/usr/local/lib/python3.11/dist-packages/scikeras/wrappers.py\", line 549, in _check_model_compatibility\n    if self.n_outputs_expected_ != len(self.model_.outputs):\n                                       ^^^^^^^^^^^^^^^^^^^\n  File \"/usr/local/lib/python3.11/dist-packages/keras/src/models/sequential.py\", line 308, in outputs\n    raise AttributeError(\nAttributeError: Sequential model 'sequential_52' has no defined outputs yet.\n\n--------------------------------------------------------------------------------\n1 fits failed with the following error:\nTraceback (most recent call last):\n  File \"/usr/local/lib/python3.11/dist-packages/sklearn/model_selection/_validation.py\", line 895, in _fit_and_score\n    estimator.fit(X_train, y_train, **fit_params)\n  File \"/usr/local/lib/python3.11/dist-packages/scikeras/wrappers.py\", line 1491, in fit\n    super().fit(X=X, y=y, sample_weight=sample_weight, **kwargs)\n  File \"/usr/local/lib/python3.11/dist-packages/scikeras/wrappers.py\", line 760, in fit\n    self._fit(\n  File \"/usr/local/lib/python3.11/dist-packages/scikeras/wrappers.py\", line 926, in _fit\n    self._check_model_compatibility(y)\n  File \"/usr/local/lib/python3.11/dist-packages/scikeras/wrappers.py\", line 549, in _check_model_compatibility\n    if self.n_outputs_expected_ != len(self.model_.outputs):\n                                       ^^^^^^^^^^^^^^^^^^^\n  File \"/usr/local/lib/python3.11/dist-packages/keras/src/models/sequential.py\", line 308, in outputs\n    raise AttributeError(\nAttributeError: Sequential model 'sequential_53' has no defined outputs yet.\n\n--------------------------------------------------------------------------------\n1 fits failed with the following error:\nTraceback (most recent call last):\n  File \"/usr/local/lib/python3.11/dist-packages/sklearn/model_selection/_validation.py\", line 895, in _fit_and_score\n    estimator.fit(X_train, y_train, **fit_params)\n  File \"/usr/local/lib/python3.11/dist-packages/scikeras/wrappers.py\", line 1491, in fit\n    super().fit(X=X, y=y, sample_weight=sample_weight, **kwargs)\n  File \"/usr/local/lib/python3.11/dist-packages/scikeras/wrappers.py\", line 760, in fit\n    self._fit(\n  File \"/usr/local/lib/python3.11/dist-packages/scikeras/wrappers.py\", line 926, in _fit\n    self._check_model_compatibility(y)\n  File \"/usr/local/lib/python3.11/dist-packages/scikeras/wrappers.py\", line 549, in _check_model_compatibility\n    if self.n_outputs_expected_ != len(self.model_.outputs):\n                                       ^^^^^^^^^^^^^^^^^^^\n  File \"/usr/local/lib/python3.11/dist-packages/keras/src/models/sequential.py\", line 308, in outputs\n    raise AttributeError(\nAttributeError: Sequential model 'sequential_54' has no defined outputs yet.\n\n--------------------------------------------------------------------------------\n1 fits failed with the following error:\nTraceback (most recent call last):\n  File \"/usr/local/lib/python3.11/dist-packages/sklearn/model_selection/_validation.py\", line 895, in _fit_and_score\n    estimator.fit(X_train, y_train, **fit_params)\n  File \"/usr/local/lib/python3.11/dist-packages/scikeras/wrappers.py\", line 1491, in fit\n    super().fit(X=X, y=y, sample_weight=sample_weight, **kwargs)\n  File \"/usr/local/lib/python3.11/dist-packages/scikeras/wrappers.py\", line 760, in fit\n    self._fit(\n  File \"/usr/local/lib/python3.11/dist-packages/scikeras/wrappers.py\", line 926, in _fit\n    self._check_model_compatibility(y)\n  File \"/usr/local/lib/python3.11/dist-packages/scikeras/wrappers.py\", line 549, in _check_model_compatibility\n    if self.n_outputs_expected_ != len(self.model_.outputs):\n                                       ^^^^^^^^^^^^^^^^^^^\n  File \"/usr/local/lib/python3.11/dist-packages/keras/src/models/sequential.py\", line 308, in outputs\n    raise AttributeError(\nAttributeError: Sequential model 'sequential_55' has no defined outputs yet.\n\n--------------------------------------------------------------------------------\n1 fits failed with the following error:\nTraceback (most recent call last):\n  File \"/usr/local/lib/python3.11/dist-packages/sklearn/model_selection/_validation.py\", line 895, in _fit_and_score\n    estimator.fit(X_train, y_train, **fit_params)\n  File \"/usr/local/lib/python3.11/dist-packages/scikeras/wrappers.py\", line 1491, in fit\n    super().fit(X=X, y=y, sample_weight=sample_weight, **kwargs)\n  File \"/usr/local/lib/python3.11/dist-packages/scikeras/wrappers.py\", line 760, in fit\n    self._fit(\n  File \"/usr/local/lib/python3.11/dist-packages/scikeras/wrappers.py\", line 926, in _fit\n    self._check_model_compatibility(y)\n  File \"/usr/local/lib/python3.11/dist-packages/scikeras/wrappers.py\", line 549, in _check_model_compatibility\n    if self.n_outputs_expected_ != len(self.model_.outputs):\n                                       ^^^^^^^^^^^^^^^^^^^\n  File \"/usr/local/lib/python3.11/dist-packages/keras/src/models/sequential.py\", line 308, in outputs\n    raise AttributeError(\nAttributeError: Sequential model 'sequential_56' has no defined outputs yet.\n\n--------------------------------------------------------------------------------\n1 fits failed with the following error:\nTraceback (most recent call last):\n  File \"/usr/local/lib/python3.11/dist-packages/sklearn/model_selection/_validation.py\", line 895, in _fit_and_score\n    estimator.fit(X_train, y_train, **fit_params)\n  File \"/usr/local/lib/python3.11/dist-packages/scikeras/wrappers.py\", line 1491, in fit\n    super().fit(X=X, y=y, sample_weight=sample_weight, **kwargs)\n  File \"/usr/local/lib/python3.11/dist-packages/scikeras/wrappers.py\", line 760, in fit\n    self._fit(\n  File \"/usr/local/lib/python3.11/dist-packages/scikeras/wrappers.py\", line 926, in _fit\n    self._check_model_compatibility(y)\n  File \"/usr/local/lib/python3.11/dist-packages/scikeras/wrappers.py\", line 549, in _check_model_compatibility\n    if self.n_outputs_expected_ != len(self.model_.outputs):\n                                       ^^^^^^^^^^^^^^^^^^^\n  File \"/usr/local/lib/python3.11/dist-packages/keras/src/models/sequential.py\", line 308, in outputs\n    raise AttributeError(\nAttributeError: Sequential model 'sequential_57' has no defined outputs yet.\n\n--------------------------------------------------------------------------------\n1 fits failed with the following error:\nTraceback (most recent call last):\n  File \"/usr/local/lib/python3.11/dist-packages/sklearn/model_selection/_validation.py\", line 895, in _fit_and_score\n    estimator.fit(X_train, y_train, **fit_params)\n  File \"/usr/local/lib/python3.11/dist-packages/scikeras/wrappers.py\", line 1491, in fit\n    super().fit(X=X, y=y, sample_weight=sample_weight, **kwargs)\n  File \"/usr/local/lib/python3.11/dist-packages/scikeras/wrappers.py\", line 760, in fit\n    self._fit(\n  File \"/usr/local/lib/python3.11/dist-packages/scikeras/wrappers.py\", line 926, in _fit\n    self._check_model_compatibility(y)\n  File \"/usr/local/lib/python3.11/dist-packages/scikeras/wrappers.py\", line 549, in _check_model_compatibility\n    if self.n_outputs_expected_ != len(self.model_.outputs):\n                                       ^^^^^^^^^^^^^^^^^^^\n  File \"/usr/local/lib/python3.11/dist-packages/keras/src/models/sequential.py\", line 308, in outputs\n    raise AttributeError(\nAttributeError: Sequential model 'sequential_58' has no defined outputs yet.\n\n--------------------------------------------------------------------------------\n1 fits failed with the following error:\nTraceback (most recent call last):\n  File \"/usr/local/lib/python3.11/dist-packages/sklearn/model_selection/_validation.py\", line 895, in _fit_and_score\n    estimator.fit(X_train, y_train, **fit_params)\n  File \"/usr/local/lib/python3.11/dist-packages/scikeras/wrappers.py\", line 1491, in fit\n    super().fit(X=X, y=y, sample_weight=sample_weight, **kwargs)\n  File \"/usr/local/lib/python3.11/dist-packages/scikeras/wrappers.py\", line 760, in fit\n    self._fit(\n  File \"/usr/local/lib/python3.11/dist-packages/scikeras/wrappers.py\", line 926, in _fit\n    self._check_model_compatibility(y)\n  File \"/usr/local/lib/python3.11/dist-packages/scikeras/wrappers.py\", line 549, in _check_model_compatibility\n    if self.n_outputs_expected_ != len(self.model_.outputs):\n                                       ^^^^^^^^^^^^^^^^^^^\n  File \"/usr/local/lib/python3.11/dist-packages/keras/src/models/sequential.py\", line 308, in outputs\n    raise AttributeError(\nAttributeError: Sequential model 'sequential_59' has no defined outputs yet.\n\n--------------------------------------------------------------------------------\n1 fits failed with the following error:\nTraceback (most recent call last):\n  File \"/usr/local/lib/python3.11/dist-packages/sklearn/model_selection/_validation.py\", line 895, in _fit_and_score\n    estimator.fit(X_train, y_train, **fit_params)\n  File \"/usr/local/lib/python3.11/dist-packages/scikeras/wrappers.py\", line 1491, in fit\n    super().fit(X=X, y=y, sample_weight=sample_weight, **kwargs)\n  File \"/usr/local/lib/python3.11/dist-packages/scikeras/wrappers.py\", line 760, in fit\n    self._fit(\n  File \"/usr/local/lib/python3.11/dist-packages/scikeras/wrappers.py\", line 926, in _fit\n    self._check_model_compatibility(y)\n  File \"/usr/local/lib/python3.11/dist-packages/scikeras/wrappers.py\", line 549, in _check_model_compatibility\n    if self.n_outputs_expected_ != len(self.model_.outputs):\n                                       ^^^^^^^^^^^^^^^^^^^\n  File \"/usr/local/lib/python3.11/dist-packages/keras/src/models/sequential.py\", line 308, in outputs\n    raise AttributeError(\nAttributeError: Sequential model 'sequential_60' has no defined outputs yet.\n\n--------------------------------------------------------------------------------\n1 fits failed with the following error:\nTraceback (most recent call last):\n  File \"/usr/local/lib/python3.11/dist-packages/sklearn/model_selection/_validation.py\", line 895, in _fit_and_score\n    estimator.fit(X_train, y_train, **fit_params)\n  File \"/usr/local/lib/python3.11/dist-packages/scikeras/wrappers.py\", line 1491, in fit\n    super().fit(X=X, y=y, sample_weight=sample_weight, **kwargs)\n  File \"/usr/local/lib/python3.11/dist-packages/scikeras/wrappers.py\", line 760, in fit\n    self._fit(\n  File \"/usr/local/lib/python3.11/dist-packages/scikeras/wrappers.py\", line 926, in _fit\n    self._check_model_compatibility(y)\n  File \"/usr/local/lib/python3.11/dist-packages/scikeras/wrappers.py\", line 549, in _check_model_compatibility\n    if self.n_outputs_expected_ != len(self.model_.outputs):\n                                       ^^^^^^^^^^^^^^^^^^^\n  File \"/usr/local/lib/python3.11/dist-packages/keras/src/models/sequential.py\", line 308, in outputs\n    raise AttributeError(\nAttributeError: Sequential model 'sequential_61' has no defined outputs yet.\n\n--------------------------------------------------------------------------------\n1 fits failed with the following error:\nTraceback (most recent call last):\n  File \"/usr/local/lib/python3.11/dist-packages/sklearn/model_selection/_validation.py\", line 895, in _fit_and_score\n    estimator.fit(X_train, y_train, **fit_params)\n  File \"/usr/local/lib/python3.11/dist-packages/scikeras/wrappers.py\", line 1491, in fit\n    super().fit(X=X, y=y, sample_weight=sample_weight, **kwargs)\n  File \"/usr/local/lib/python3.11/dist-packages/scikeras/wrappers.py\", line 760, in fit\n    self._fit(\n  File \"/usr/local/lib/python3.11/dist-packages/scikeras/wrappers.py\", line 926, in _fit\n    self._check_model_compatibility(y)\n  File \"/usr/local/lib/python3.11/dist-packages/scikeras/wrappers.py\", line 549, in _check_model_compatibility\n    if self.n_outputs_expected_ != len(self.model_.outputs):\n                                       ^^^^^^^^^^^^^^^^^^^\n  File \"/usr/local/lib/python3.11/dist-packages/keras/src/models/sequential.py\", line 308, in outputs\n    raise AttributeError(\nAttributeError: Sequential model 'sequential_62' has no defined outputs yet.\n\n--------------------------------------------------------------------------------\n1 fits failed with the following error:\nTraceback (most recent call last):\n  File \"/usr/local/lib/python3.11/dist-packages/sklearn/model_selection/_validation.py\", line 895, in _fit_and_score\n    estimator.fit(X_train, y_train, **fit_params)\n  File \"/usr/local/lib/python3.11/dist-packages/scikeras/wrappers.py\", line 1491, in fit\n    super().fit(X=X, y=y, sample_weight=sample_weight, **kwargs)\n  File \"/usr/local/lib/python3.11/dist-packages/scikeras/wrappers.py\", line 760, in fit\n    self._fit(\n  File \"/usr/local/lib/python3.11/dist-packages/scikeras/wrappers.py\", line 926, in _fit\n    self._check_model_compatibility(y)\n  File \"/usr/local/lib/python3.11/dist-packages/scikeras/wrappers.py\", line 549, in _check_model_compatibility\n    if self.n_outputs_expected_ != len(self.model_.outputs):\n                                       ^^^^^^^^^^^^^^^^^^^\n  File \"/usr/local/lib/python3.11/dist-packages/keras/src/models/sequential.py\", line 308, in outputs\n    raise AttributeError(\nAttributeError: Sequential model 'sequential_63' has no defined outputs yet.\n\n--------------------------------------------------------------------------------\n1 fits failed with the following error:\nTraceback (most recent call last):\n  File \"/usr/local/lib/python3.11/dist-packages/sklearn/model_selection/_validation.py\", line 895, in _fit_and_score\n    estimator.fit(X_train, y_train, **fit_params)\n  File \"/usr/local/lib/python3.11/dist-packages/scikeras/wrappers.py\", line 1491, in fit\n    super().fit(X=X, y=y, sample_weight=sample_weight, **kwargs)\n  File \"/usr/local/lib/python3.11/dist-packages/scikeras/wrappers.py\", line 760, in fit\n    self._fit(\n  File \"/usr/local/lib/python3.11/dist-packages/scikeras/wrappers.py\", line 926, in _fit\n    self._check_model_compatibility(y)\n  File \"/usr/local/lib/python3.11/dist-packages/scikeras/wrappers.py\", line 549, in _check_model_compatibility\n    if self.n_outputs_expected_ != len(self.model_.outputs):\n                                       ^^^^^^^^^^^^^^^^^^^\n  File \"/usr/local/lib/python3.11/dist-packages/keras/src/models/sequential.py\", line 308, in outputs\n    raise AttributeError(\nAttributeError: Sequential model 'sequential_64' has no defined outputs yet.\n\n--------------------------------------------------------------------------------\n1 fits failed with the following error:\nTraceback (most recent call last):\n  File \"/usr/local/lib/python3.11/dist-packages/sklearn/model_selection/_validation.py\", line 895, in _fit_and_score\n    estimator.fit(X_train, y_train, **fit_params)\n  File \"/usr/local/lib/python3.11/dist-packages/scikeras/wrappers.py\", line 1491, in fit\n    super().fit(X=X, y=y, sample_weight=sample_weight, **kwargs)\n  File \"/usr/local/lib/python3.11/dist-packages/scikeras/wrappers.py\", line 760, in fit\n    self._fit(\n  File \"/usr/local/lib/python3.11/dist-packages/scikeras/wrappers.py\", line 926, in _fit\n    self._check_model_compatibility(y)\n  File \"/usr/local/lib/python3.11/dist-packages/scikeras/wrappers.py\", line 549, in _check_model_compatibility\n    if self.n_outputs_expected_ != len(self.model_.outputs):\n                                       ^^^^^^^^^^^^^^^^^^^\n  File \"/usr/local/lib/python3.11/dist-packages/keras/src/models/sequential.py\", line 308, in outputs\n    raise AttributeError(\nAttributeError: Sequential model 'sequential_65' has no defined outputs yet.\n\n--------------------------------------------------------------------------------\n1 fits failed with the following error:\nTraceback (most recent call last):\n  File \"/usr/local/lib/python3.11/dist-packages/sklearn/model_selection/_validation.py\", line 895, in _fit_and_score\n    estimator.fit(X_train, y_train, **fit_params)\n  File \"/usr/local/lib/python3.11/dist-packages/scikeras/wrappers.py\", line 1491, in fit\n    super().fit(X=X, y=y, sample_weight=sample_weight, **kwargs)\n  File \"/usr/local/lib/python3.11/dist-packages/scikeras/wrappers.py\", line 760, in fit\n    self._fit(\n  File \"/usr/local/lib/python3.11/dist-packages/scikeras/wrappers.py\", line 926, in _fit\n    self._check_model_compatibility(y)\n  File \"/usr/local/lib/python3.11/dist-packages/scikeras/wrappers.py\", line 549, in _check_model_compatibility\n    if self.n_outputs_expected_ != len(self.model_.outputs):\n                                       ^^^^^^^^^^^^^^^^^^^\n  File \"/usr/local/lib/python3.11/dist-packages/keras/src/models/sequential.py\", line 308, in outputs\n    raise AttributeError(\nAttributeError: Sequential model 'sequential_66' has no defined outputs yet.\n\n--------------------------------------------------------------------------------\n1 fits failed with the following error:\nTraceback (most recent call last):\n  File \"/usr/local/lib/python3.11/dist-packages/sklearn/model_selection/_validation.py\", line 895, in _fit_and_score\n    estimator.fit(X_train, y_train, **fit_params)\n  File \"/usr/local/lib/python3.11/dist-packages/scikeras/wrappers.py\", line 1491, in fit\n    super().fit(X=X, y=y, sample_weight=sample_weight, **kwargs)\n  File \"/usr/local/lib/python3.11/dist-packages/scikeras/wrappers.py\", line 760, in fit\n    self._fit(\n  File \"/usr/local/lib/python3.11/dist-packages/scikeras/wrappers.py\", line 926, in _fit\n    self._check_model_compatibility(y)\n  File \"/usr/local/lib/python3.11/dist-packages/scikeras/wrappers.py\", line 549, in _check_model_compatibility\n    if self.n_outputs_expected_ != len(self.model_.outputs):\n                                       ^^^^^^^^^^^^^^^^^^^\n  File \"/usr/local/lib/python3.11/dist-packages/keras/src/models/sequential.py\", line 308, in outputs\n    raise AttributeError(\nAttributeError: Sequential model 'sequential_67' has no defined outputs yet.\n\n--------------------------------------------------------------------------------\n1 fits failed with the following error:\nTraceback (most recent call last):\n  File \"/usr/local/lib/python3.11/dist-packages/sklearn/model_selection/_validation.py\", line 895, in _fit_and_score\n    estimator.fit(X_train, y_train, **fit_params)\n  File \"/usr/local/lib/python3.11/dist-packages/scikeras/wrappers.py\", line 1491, in fit\n    super().fit(X=X, y=y, sample_weight=sample_weight, **kwargs)\n  File \"/usr/local/lib/python3.11/dist-packages/scikeras/wrappers.py\", line 760, in fit\n    self._fit(\n  File \"/usr/local/lib/python3.11/dist-packages/scikeras/wrappers.py\", line 926, in _fit\n    self._check_model_compatibility(y)\n  File \"/usr/local/lib/python3.11/dist-packages/scikeras/wrappers.py\", line 549, in _check_model_compatibility\n    if self.n_outputs_expected_ != len(self.model_.outputs):\n                                       ^^^^^^^^^^^^^^^^^^^\n  File \"/usr/local/lib/python3.11/dist-packages/keras/src/models/sequential.py\", line 308, in outputs\n    raise AttributeError(\nAttributeError: Sequential model 'sequential_68' has no defined outputs yet.\n\n--------------------------------------------------------------------------------\n1 fits failed with the following error:\nTraceback (most recent call last):\n  File \"/usr/local/lib/python3.11/dist-packages/sklearn/model_selection/_validation.py\", line 895, in _fit_and_score\n    estimator.fit(X_train, y_train, **fit_params)\n  File \"/usr/local/lib/python3.11/dist-packages/scikeras/wrappers.py\", line 1491, in fit\n    super().fit(X=X, y=y, sample_weight=sample_weight, **kwargs)\n  File \"/usr/local/lib/python3.11/dist-packages/scikeras/wrappers.py\", line 760, in fit\n    self._fit(\n  File \"/usr/local/lib/python3.11/dist-packages/scikeras/wrappers.py\", line 926, in _fit\n    self._check_model_compatibility(y)\n  File \"/usr/local/lib/python3.11/dist-packages/scikeras/wrappers.py\", line 549, in _check_model_compatibility\n    if self.n_outputs_expected_ != len(self.model_.outputs):\n                                       ^^^^^^^^^^^^^^^^^^^\n  File \"/usr/local/lib/python3.11/dist-packages/keras/src/models/sequential.py\", line 308, in outputs\n    raise AttributeError(\nAttributeError: Sequential model 'sequential_69' has no defined outputs yet.\n\n--------------------------------------------------------------------------------\n1 fits failed with the following error:\nTraceback (most recent call last):\n  File \"/usr/local/lib/python3.11/dist-packages/sklearn/model_selection/_validation.py\", line 895, in _fit_and_score\n    estimator.fit(X_train, y_train, **fit_params)\n  File \"/usr/local/lib/python3.11/dist-packages/scikeras/wrappers.py\", line 1491, in fit\n    super().fit(X=X, y=y, sample_weight=sample_weight, **kwargs)\n  File \"/usr/local/lib/python3.11/dist-packages/scikeras/wrappers.py\", line 760, in fit\n    self._fit(\n  File \"/usr/local/lib/python3.11/dist-packages/scikeras/wrappers.py\", line 926, in _fit\n    self._check_model_compatibility(y)\n  File \"/usr/local/lib/python3.11/dist-packages/scikeras/wrappers.py\", line 549, in _check_model_compatibility\n    if self.n_outputs_expected_ != len(self.model_.outputs):\n                                       ^^^^^^^^^^^^^^^^^^^\n  File \"/usr/local/lib/python3.11/dist-packages/keras/src/models/sequential.py\", line 308, in outputs\n    raise AttributeError(\nAttributeError: Sequential model 'sequential_70' has no defined outputs yet.\n\n--------------------------------------------------------------------------------\n1 fits failed with the following error:\nTraceback (most recent call last):\n  File \"/usr/local/lib/python3.11/dist-packages/sklearn/model_selection/_validation.py\", line 895, in _fit_and_score\n    estimator.fit(X_train, y_train, **fit_params)\n  File \"/usr/local/lib/python3.11/dist-packages/scikeras/wrappers.py\", line 1491, in fit\n    super().fit(X=X, y=y, sample_weight=sample_weight, **kwargs)\n  File \"/usr/local/lib/python3.11/dist-packages/scikeras/wrappers.py\", line 760, in fit\n    self._fit(\n  File \"/usr/local/lib/python3.11/dist-packages/scikeras/wrappers.py\", line 926, in _fit\n    self._check_model_compatibility(y)\n  File \"/usr/local/lib/python3.11/dist-packages/scikeras/wrappers.py\", line 549, in _check_model_compatibility\n    if self.n_outputs_expected_ != len(self.model_.outputs):\n                                       ^^^^^^^^^^^^^^^^^^^\n  File \"/usr/local/lib/python3.11/dist-packages/keras/src/models/sequential.py\", line 308, in outputs\n    raise AttributeError(\nAttributeError: Sequential model 'sequential_71' has no defined outputs yet.\n\n--------------------------------------------------------------------------------\n1 fits failed with the following error:\nTraceback (most recent call last):\n  File \"/usr/local/lib/python3.11/dist-packages/sklearn/model_selection/_validation.py\", line 895, in _fit_and_score\n    estimator.fit(X_train, y_train, **fit_params)\n  File \"/usr/local/lib/python3.11/dist-packages/scikeras/wrappers.py\", line 1491, in fit\n    super().fit(X=X, y=y, sample_weight=sample_weight, **kwargs)\n  File \"/usr/local/lib/python3.11/dist-packages/scikeras/wrappers.py\", line 760, in fit\n    self._fit(\n  File \"/usr/local/lib/python3.11/dist-packages/scikeras/wrappers.py\", line 926, in _fit\n    self._check_model_compatibility(y)\n  File \"/usr/local/lib/python3.11/dist-packages/scikeras/wrappers.py\", line 549, in _check_model_compatibility\n    if self.n_outputs_expected_ != len(self.model_.outputs):\n                                       ^^^^^^^^^^^^^^^^^^^\n  File \"/usr/local/lib/python3.11/dist-packages/keras/src/models/sequential.py\", line 308, in outputs\n    raise AttributeError(\nAttributeError: Sequential model 'sequential_72' has no defined outputs yet.\n\n--------------------------------------------------------------------------------\n1 fits failed with the following error:\nTraceback (most recent call last):\n  File \"/usr/local/lib/python3.11/dist-packages/sklearn/model_selection/_validation.py\", line 895, in _fit_and_score\n    estimator.fit(X_train, y_train, **fit_params)\n  File \"/usr/local/lib/python3.11/dist-packages/scikeras/wrappers.py\", line 1491, in fit\n    super().fit(X=X, y=y, sample_weight=sample_weight, **kwargs)\n  File \"/usr/local/lib/python3.11/dist-packages/scikeras/wrappers.py\", line 760, in fit\n    self._fit(\n  File \"/usr/local/lib/python3.11/dist-packages/scikeras/wrappers.py\", line 926, in _fit\n    self._check_model_compatibility(y)\n  File \"/usr/local/lib/python3.11/dist-packages/scikeras/wrappers.py\", line 549, in _check_model_compatibility\n    if self.n_outputs_expected_ != len(self.model_.outputs):\n                                       ^^^^^^^^^^^^^^^^^^^\n  File \"/usr/local/lib/python3.11/dist-packages/keras/src/models/sequential.py\", line 308, in outputs\n    raise AttributeError(\nAttributeError: Sequential model 'sequential_73' has no defined outputs yet.\n\n--------------------------------------------------------------------------------\n1 fits failed with the following error:\nTraceback (most recent call last):\n  File \"/usr/local/lib/python3.11/dist-packages/sklearn/model_selection/_validation.py\", line 895, in _fit_and_score\n    estimator.fit(X_train, y_train, **fit_params)\n  File \"/usr/local/lib/python3.11/dist-packages/scikeras/wrappers.py\", line 1491, in fit\n    super().fit(X=X, y=y, sample_weight=sample_weight, **kwargs)\n  File \"/usr/local/lib/python3.11/dist-packages/scikeras/wrappers.py\", line 760, in fit\n    self._fit(\n  File \"/usr/local/lib/python3.11/dist-packages/scikeras/wrappers.py\", line 926, in _fit\n    self._check_model_compatibility(y)\n  File \"/usr/local/lib/python3.11/dist-packages/scikeras/wrappers.py\", line 549, in _check_model_compatibility\n    if self.n_outputs_expected_ != len(self.model_.outputs):\n                                       ^^^^^^^^^^^^^^^^^^^\n  File \"/usr/local/lib/python3.11/dist-packages/keras/src/models/sequential.py\", line 308, in outputs\n    raise AttributeError(\nAttributeError: Sequential model 'sequential_74' has no defined outputs yet.\n\n--------------------------------------------------------------------------------\n1 fits failed with the following error:\nTraceback (most recent call last):\n  File \"/usr/local/lib/python3.11/dist-packages/sklearn/model_selection/_validation.py\", line 895, in _fit_and_score\n    estimator.fit(X_train, y_train, **fit_params)\n  File \"/usr/local/lib/python3.11/dist-packages/scikeras/wrappers.py\", line 1491, in fit\n    super().fit(X=X, y=y, sample_weight=sample_weight, **kwargs)\n  File \"/usr/local/lib/python3.11/dist-packages/scikeras/wrappers.py\", line 760, in fit\n    self._fit(\n  File \"/usr/local/lib/python3.11/dist-packages/scikeras/wrappers.py\", line 926, in _fit\n    self._check_model_compatibility(y)\n  File \"/usr/local/lib/python3.11/dist-packages/scikeras/wrappers.py\", line 549, in _check_model_compatibility\n    if self.n_outputs_expected_ != len(self.model_.outputs):\n                                       ^^^^^^^^^^^^^^^^^^^\n  File \"/usr/local/lib/python3.11/dist-packages/keras/src/models/sequential.py\", line 308, in outputs\n    raise AttributeError(\nAttributeError: Sequential model 'sequential_75' has no defined outputs yet.\n\n--------------------------------------------------------------------------------\n1 fits failed with the following error:\nTraceback (most recent call last):\n  File \"/usr/local/lib/python3.11/dist-packages/sklearn/model_selection/_validation.py\", line 895, in _fit_and_score\n    estimator.fit(X_train, y_train, **fit_params)\n  File \"/usr/local/lib/python3.11/dist-packages/scikeras/wrappers.py\", line 1491, in fit\n    super().fit(X=X, y=y, sample_weight=sample_weight, **kwargs)\n  File \"/usr/local/lib/python3.11/dist-packages/scikeras/wrappers.py\", line 760, in fit\n    self._fit(\n  File \"/usr/local/lib/python3.11/dist-packages/scikeras/wrappers.py\", line 926, in _fit\n    self._check_model_compatibility(y)\n  File \"/usr/local/lib/python3.11/dist-packages/scikeras/wrappers.py\", line 549, in _check_model_compatibility\n    if self.n_outputs_expected_ != len(self.model_.outputs):\n                                       ^^^^^^^^^^^^^^^^^^^\n  File \"/usr/local/lib/python3.11/dist-packages/keras/src/models/sequential.py\", line 308, in outputs\n    raise AttributeError(\nAttributeError: Sequential model 'sequential_76' has no defined outputs yet.\n\n--------------------------------------------------------------------------------\n1 fits failed with the following error:\nTraceback (most recent call last):\n  File \"/usr/local/lib/python3.11/dist-packages/sklearn/model_selection/_validation.py\", line 895, in _fit_and_score\n    estimator.fit(X_train, y_train, **fit_params)\n  File \"/usr/local/lib/python3.11/dist-packages/scikeras/wrappers.py\", line 1491, in fit\n    super().fit(X=X, y=y, sample_weight=sample_weight, **kwargs)\n  File \"/usr/local/lib/python3.11/dist-packages/scikeras/wrappers.py\", line 760, in fit\n    self._fit(\n  File \"/usr/local/lib/python3.11/dist-packages/scikeras/wrappers.py\", line 926, in _fit\n    self._check_model_compatibility(y)\n  File \"/usr/local/lib/python3.11/dist-packages/scikeras/wrappers.py\", line 549, in _check_model_compatibility\n    if self.n_outputs_expected_ != len(self.model_.outputs):\n                                       ^^^^^^^^^^^^^^^^^^^\n  File \"/usr/local/lib/python3.11/dist-packages/keras/src/models/sequential.py\", line 308, in outputs\n    raise AttributeError(\nAttributeError: Sequential model 'sequential_77' has no defined outputs yet.\n\n--------------------------------------------------------------------------------\n1 fits failed with the following error:\nTraceback (most recent call last):\n  File \"/usr/local/lib/python3.11/dist-packages/sklearn/model_selection/_validation.py\", line 895, in _fit_and_score\n    estimator.fit(X_train, y_train, **fit_params)\n  File \"/usr/local/lib/python3.11/dist-packages/scikeras/wrappers.py\", line 1491, in fit\n    super().fit(X=X, y=y, sample_weight=sample_weight, **kwargs)\n  File \"/usr/local/lib/python3.11/dist-packages/scikeras/wrappers.py\", line 760, in fit\n    self._fit(\n  File \"/usr/local/lib/python3.11/dist-packages/scikeras/wrappers.py\", line 926, in _fit\n    self._check_model_compatibility(y)\n  File \"/usr/local/lib/python3.11/dist-packages/scikeras/wrappers.py\", line 549, in _check_model_compatibility\n    if self.n_outputs_expected_ != len(self.model_.outputs):\n                                       ^^^^^^^^^^^^^^^^^^^\n  File \"/usr/local/lib/python3.11/dist-packages/keras/src/models/sequential.py\", line 308, in outputs\n    raise AttributeError(\nAttributeError: Sequential model 'sequential_78' has no defined outputs yet.\n\n--------------------------------------------------------------------------------\n1 fits failed with the following error:\nTraceback (most recent call last):\n  File \"/usr/local/lib/python3.11/dist-packages/sklearn/model_selection/_validation.py\", line 895, in _fit_and_score\n    estimator.fit(X_train, y_train, **fit_params)\n  File \"/usr/local/lib/python3.11/dist-packages/scikeras/wrappers.py\", line 1491, in fit\n    super().fit(X=X, y=y, sample_weight=sample_weight, **kwargs)\n  File \"/usr/local/lib/python3.11/dist-packages/scikeras/wrappers.py\", line 760, in fit\n    self._fit(\n  File \"/usr/local/lib/python3.11/dist-packages/scikeras/wrappers.py\", line 926, in _fit\n    self._check_model_compatibility(y)\n  File \"/usr/local/lib/python3.11/dist-packages/scikeras/wrappers.py\", line 549, in _check_model_compatibility\n    if self.n_outputs_expected_ != len(self.model_.outputs):\n                                       ^^^^^^^^^^^^^^^^^^^\n  File \"/usr/local/lib/python3.11/dist-packages/keras/src/models/sequential.py\", line 308, in outputs\n    raise AttributeError(\nAttributeError: Sequential model 'sequential_79' has no defined outputs yet.\n\n--------------------------------------------------------------------------------\n1 fits failed with the following error:\nTraceback (most recent call last):\n  File \"/usr/local/lib/python3.11/dist-packages/sklearn/model_selection/_validation.py\", line 895, in _fit_and_score\n    estimator.fit(X_train, y_train, **fit_params)\n  File \"/usr/local/lib/python3.11/dist-packages/scikeras/wrappers.py\", line 1491, in fit\n    super().fit(X=X, y=y, sample_weight=sample_weight, **kwargs)\n  File \"/usr/local/lib/python3.11/dist-packages/scikeras/wrappers.py\", line 760, in fit\n    self._fit(\n  File \"/usr/local/lib/python3.11/dist-packages/scikeras/wrappers.py\", line 926, in _fit\n    self._check_model_compatibility(y)\n  File \"/usr/local/lib/python3.11/dist-packages/scikeras/wrappers.py\", line 549, in _check_model_compatibility\n    if self.n_outputs_expected_ != len(self.model_.outputs):\n                                       ^^^^^^^^^^^^^^^^^^^\n  File \"/usr/local/lib/python3.11/dist-packages/keras/src/models/sequential.py\", line 308, in outputs\n    raise AttributeError(\nAttributeError: Sequential model 'sequential_80' has no defined outputs yet.\n\n--------------------------------------------------------------------------------\n1 fits failed with the following error:\nTraceback (most recent call last):\n  File \"/usr/local/lib/python3.11/dist-packages/sklearn/model_selection/_validation.py\", line 895, in _fit_and_score\n    estimator.fit(X_train, y_train, **fit_params)\n  File \"/usr/local/lib/python3.11/dist-packages/scikeras/wrappers.py\", line 1491, in fit\n    super().fit(X=X, y=y, sample_weight=sample_weight, **kwargs)\n  File \"/usr/local/lib/python3.11/dist-packages/scikeras/wrappers.py\", line 760, in fit\n    self._fit(\n  File \"/usr/local/lib/python3.11/dist-packages/scikeras/wrappers.py\", line 926, in _fit\n    self._check_model_compatibility(y)\n  File \"/usr/local/lib/python3.11/dist-packages/scikeras/wrappers.py\", line 549, in _check_model_compatibility\n    if self.n_outputs_expected_ != len(self.model_.outputs):\n                                       ^^^^^^^^^^^^^^^^^^^\n  File \"/usr/local/lib/python3.11/dist-packages/keras/src/models/sequential.py\", line 308, in outputs\n    raise AttributeError(\nAttributeError: Sequential model 'sequential_81' has no defined outputs yet.\n\n--------------------------------------------------------------------------------\n1 fits failed with the following error:\nTraceback (most recent call last):\n  File \"/usr/local/lib/python3.11/dist-packages/sklearn/model_selection/_validation.py\", line 895, in _fit_and_score\n    estimator.fit(X_train, y_train, **fit_params)\n  File \"/usr/local/lib/python3.11/dist-packages/scikeras/wrappers.py\", line 1491, in fit\n    super().fit(X=X, y=y, sample_weight=sample_weight, **kwargs)\n  File \"/usr/local/lib/python3.11/dist-packages/scikeras/wrappers.py\", line 760, in fit\n    self._fit(\n  File \"/usr/local/lib/python3.11/dist-packages/scikeras/wrappers.py\", line 926, in _fit\n    self._check_model_compatibility(y)\n  File \"/usr/local/lib/python3.11/dist-packages/scikeras/wrappers.py\", line 549, in _check_model_compatibility\n    if self.n_outputs_expected_ != len(self.model_.outputs):\n                                       ^^^^^^^^^^^^^^^^^^^\n  File \"/usr/local/lib/python3.11/dist-packages/keras/src/models/sequential.py\", line 308, in outputs\n    raise AttributeError(\nAttributeError: Sequential model 'sequential_82' has no defined outputs yet.\n\n--------------------------------------------------------------------------------\n1 fits failed with the following error:\nTraceback (most recent call last):\n  File \"/usr/local/lib/python3.11/dist-packages/sklearn/model_selection/_validation.py\", line 895, in _fit_and_score\n    estimator.fit(X_train, y_train, **fit_params)\n  File \"/usr/local/lib/python3.11/dist-packages/scikeras/wrappers.py\", line 1491, in fit\n    super().fit(X=X, y=y, sample_weight=sample_weight, **kwargs)\n  File \"/usr/local/lib/python3.11/dist-packages/scikeras/wrappers.py\", line 760, in fit\n    self._fit(\n  File \"/usr/local/lib/python3.11/dist-packages/scikeras/wrappers.py\", line 926, in _fit\n    self._check_model_compatibility(y)\n  File \"/usr/local/lib/python3.11/dist-packages/scikeras/wrappers.py\", line 549, in _check_model_compatibility\n    if self.n_outputs_expected_ != len(self.model_.outputs):\n                                       ^^^^^^^^^^^^^^^^^^^\n  File \"/usr/local/lib/python3.11/dist-packages/keras/src/models/sequential.py\", line 308, in outputs\n    raise AttributeError(\nAttributeError: Sequential model 'sequential_83' has no defined outputs yet.\n\n--------------------------------------------------------------------------------\n1 fits failed with the following error:\nTraceback (most recent call last):\n  File \"/usr/local/lib/python3.11/dist-packages/sklearn/model_selection/_validation.py\", line 895, in _fit_and_score\n    estimator.fit(X_train, y_train, **fit_params)\n  File \"/usr/local/lib/python3.11/dist-packages/scikeras/wrappers.py\", line 1491, in fit\n    super().fit(X=X, y=y, sample_weight=sample_weight, **kwargs)\n  File \"/usr/local/lib/python3.11/dist-packages/scikeras/wrappers.py\", line 760, in fit\n    self._fit(\n  File \"/usr/local/lib/python3.11/dist-packages/scikeras/wrappers.py\", line 926, in _fit\n    self._check_model_compatibility(y)\n  File \"/usr/local/lib/python3.11/dist-packages/scikeras/wrappers.py\", line 549, in _check_model_compatibility\n    if self.n_outputs_expected_ != len(self.model_.outputs):\n                                       ^^^^^^^^^^^^^^^^^^^\n  File \"/usr/local/lib/python3.11/dist-packages/keras/src/models/sequential.py\", line 308, in outputs\n    raise AttributeError(\nAttributeError: Sequential model 'sequential_84' has no defined outputs yet.\n\n--------------------------------------------------------------------------------\n1 fits failed with the following error:\nTraceback (most recent call last):\n  File \"/usr/local/lib/python3.11/dist-packages/sklearn/model_selection/_validation.py\", line 895, in _fit_and_score\n    estimator.fit(X_train, y_train, **fit_params)\n  File \"/usr/local/lib/python3.11/dist-packages/scikeras/wrappers.py\", line 1491, in fit\n    super().fit(X=X, y=y, sample_weight=sample_weight, **kwargs)\n  File \"/usr/local/lib/python3.11/dist-packages/scikeras/wrappers.py\", line 760, in fit\n    self._fit(\n  File \"/usr/local/lib/python3.11/dist-packages/scikeras/wrappers.py\", line 926, in _fit\n    self._check_model_compatibility(y)\n  File \"/usr/local/lib/python3.11/dist-packages/scikeras/wrappers.py\", line 549, in _check_model_compatibility\n    if self.n_outputs_expected_ != len(self.model_.outputs):\n                                       ^^^^^^^^^^^^^^^^^^^\n  File \"/usr/local/lib/python3.11/dist-packages/keras/src/models/sequential.py\", line 308, in outputs\n    raise AttributeError(\nAttributeError: Sequential model 'sequential_85' has no defined outputs yet.\n\n--------------------------------------------------------------------------------\n1 fits failed with the following error:\nTraceback (most recent call last):\n  File \"/usr/local/lib/python3.11/dist-packages/sklearn/model_selection/_validation.py\", line 895, in _fit_and_score\n    estimator.fit(X_train, y_train, **fit_params)\n  File \"/usr/local/lib/python3.11/dist-packages/scikeras/wrappers.py\", line 1491, in fit\n    super().fit(X=X, y=y, sample_weight=sample_weight, **kwargs)\n  File \"/usr/local/lib/python3.11/dist-packages/scikeras/wrappers.py\", line 760, in fit\n    self._fit(\n  File \"/usr/local/lib/python3.11/dist-packages/scikeras/wrappers.py\", line 926, in _fit\n    self._check_model_compatibility(y)\n  File \"/usr/local/lib/python3.11/dist-packages/scikeras/wrappers.py\", line 549, in _check_model_compatibility\n    if self.n_outputs_expected_ != len(self.model_.outputs):\n                                       ^^^^^^^^^^^^^^^^^^^\n  File \"/usr/local/lib/python3.11/dist-packages/keras/src/models/sequential.py\", line 308, in outputs\n    raise AttributeError(\nAttributeError: Sequential model 'sequential_86' has no defined outputs yet.\n\n--------------------------------------------------------------------------------\n1 fits failed with the following error:\nTraceback (most recent call last):\n  File \"/usr/local/lib/python3.11/dist-packages/sklearn/model_selection/_validation.py\", line 895, in _fit_and_score\n    estimator.fit(X_train, y_train, **fit_params)\n  File \"/usr/local/lib/python3.11/dist-packages/scikeras/wrappers.py\", line 1491, in fit\n    super().fit(X=X, y=y, sample_weight=sample_weight, **kwargs)\n  File \"/usr/local/lib/python3.11/dist-packages/scikeras/wrappers.py\", line 760, in fit\n    self._fit(\n  File \"/usr/local/lib/python3.11/dist-packages/scikeras/wrappers.py\", line 926, in _fit\n    self._check_model_compatibility(y)\n  File \"/usr/local/lib/python3.11/dist-packages/scikeras/wrappers.py\", line 549, in _check_model_compatibility\n    if self.n_outputs_expected_ != len(self.model_.outputs):\n                                       ^^^^^^^^^^^^^^^^^^^\n  File \"/usr/local/lib/python3.11/dist-packages/keras/src/models/sequential.py\", line 308, in outputs\n    raise AttributeError(\nAttributeError: Sequential model 'sequential_87' has no defined outputs yet.\n\n--------------------------------------------------------------------------------\n1 fits failed with the following error:\nTraceback (most recent call last):\n  File \"/usr/local/lib/python3.11/dist-packages/sklearn/model_selection/_validation.py\", line 895, in _fit_and_score\n    estimator.fit(X_train, y_train, **fit_params)\n  File \"/usr/local/lib/python3.11/dist-packages/scikeras/wrappers.py\", line 1491, in fit\n    super().fit(X=X, y=y, sample_weight=sample_weight, **kwargs)\n  File \"/usr/local/lib/python3.11/dist-packages/scikeras/wrappers.py\", line 760, in fit\n    self._fit(\n  File \"/usr/local/lib/python3.11/dist-packages/scikeras/wrappers.py\", line 926, in _fit\n    self._check_model_compatibility(y)\n  File \"/usr/local/lib/python3.11/dist-packages/scikeras/wrappers.py\", line 549, in _check_model_compatibility\n    if self.n_outputs_expected_ != len(self.model_.outputs):\n                                       ^^^^^^^^^^^^^^^^^^^\n  File \"/usr/local/lib/python3.11/dist-packages/keras/src/models/sequential.py\", line 308, in outputs\n    raise AttributeError(\nAttributeError: Sequential model 'sequential_88' has no defined outputs yet.\n\n--------------------------------------------------------------------------------\n1 fits failed with the following error:\nTraceback (most recent call last):\n  File \"/usr/local/lib/python3.11/dist-packages/sklearn/model_selection/_validation.py\", line 895, in _fit_and_score\n    estimator.fit(X_train, y_train, **fit_params)\n  File \"/usr/local/lib/python3.11/dist-packages/scikeras/wrappers.py\", line 1491, in fit\n    super().fit(X=X, y=y, sample_weight=sample_weight, **kwargs)\n  File \"/usr/local/lib/python3.11/dist-packages/scikeras/wrappers.py\", line 760, in fit\n    self._fit(\n  File \"/usr/local/lib/python3.11/dist-packages/scikeras/wrappers.py\", line 926, in _fit\n    self._check_model_compatibility(y)\n  File \"/usr/local/lib/python3.11/dist-packages/scikeras/wrappers.py\", line 549, in _check_model_compatibility\n    if self.n_outputs_expected_ != len(self.model_.outputs):\n                                       ^^^^^^^^^^^^^^^^^^^\n  File \"/usr/local/lib/python3.11/dist-packages/keras/src/models/sequential.py\", line 308, in outputs\n    raise AttributeError(\nAttributeError: Sequential model 'sequential_89' has no defined outputs yet.\n\n--------------------------------------------------------------------------------\n1 fits failed with the following error:\nTraceback (most recent call last):\n  File \"/usr/local/lib/python3.11/dist-packages/sklearn/model_selection/_validation.py\", line 895, in _fit_and_score\n    estimator.fit(X_train, y_train, **fit_params)\n  File \"/usr/local/lib/python3.11/dist-packages/scikeras/wrappers.py\", line 1491, in fit\n    super().fit(X=X, y=y, sample_weight=sample_weight, **kwargs)\n  File \"/usr/local/lib/python3.11/dist-packages/scikeras/wrappers.py\", line 760, in fit\n    self._fit(\n  File \"/usr/local/lib/python3.11/dist-packages/scikeras/wrappers.py\", line 926, in _fit\n    self._check_model_compatibility(y)\n  File \"/usr/local/lib/python3.11/dist-packages/scikeras/wrappers.py\", line 549, in _check_model_compatibility\n    if self.n_outputs_expected_ != len(self.model_.outputs):\n                                       ^^^^^^^^^^^^^^^^^^^\n  File \"/usr/local/lib/python3.11/dist-packages/keras/src/models/sequential.py\", line 308, in outputs\n    raise AttributeError(\nAttributeError: Sequential model 'sequential_90' has no defined outputs yet.\n\n--------------------------------------------------------------------------------\n1 fits failed with the following error:\nTraceback (most recent call last):\n  File \"/usr/local/lib/python3.11/dist-packages/sklearn/model_selection/_validation.py\", line 895, in _fit_and_score\n    estimator.fit(X_train, y_train, **fit_params)\n  File \"/usr/local/lib/python3.11/dist-packages/scikeras/wrappers.py\", line 1491, in fit\n    super().fit(X=X, y=y, sample_weight=sample_weight, **kwargs)\n  File \"/usr/local/lib/python3.11/dist-packages/scikeras/wrappers.py\", line 760, in fit\n    self._fit(\n  File \"/usr/local/lib/python3.11/dist-packages/scikeras/wrappers.py\", line 926, in _fit\n    self._check_model_compatibility(y)\n  File \"/usr/local/lib/python3.11/dist-packages/scikeras/wrappers.py\", line 549, in _check_model_compatibility\n    if self.n_outputs_expected_ != len(self.model_.outputs):\n                                       ^^^^^^^^^^^^^^^^^^^\n  File \"/usr/local/lib/python3.11/dist-packages/keras/src/models/sequential.py\", line 308, in outputs\n    raise AttributeError(\nAttributeError: Sequential model 'sequential_91' has no defined outputs yet.\n\n--------------------------------------------------------------------------------\n1 fits failed with the following error:\nTraceback (most recent call last):\n  File \"/usr/local/lib/python3.11/dist-packages/sklearn/model_selection/_validation.py\", line 895, in _fit_and_score\n    estimator.fit(X_train, y_train, **fit_params)\n  File \"/usr/local/lib/python3.11/dist-packages/scikeras/wrappers.py\", line 1491, in fit\n    super().fit(X=X, y=y, sample_weight=sample_weight, **kwargs)\n  File \"/usr/local/lib/python3.11/dist-packages/scikeras/wrappers.py\", line 760, in fit\n    self._fit(\n  File \"/usr/local/lib/python3.11/dist-packages/scikeras/wrappers.py\", line 926, in _fit\n    self._check_model_compatibility(y)\n  File \"/usr/local/lib/python3.11/dist-packages/scikeras/wrappers.py\", line 549, in _check_model_compatibility\n    if self.n_outputs_expected_ != len(self.model_.outputs):\n                                       ^^^^^^^^^^^^^^^^^^^\n  File \"/usr/local/lib/python3.11/dist-packages/keras/src/models/sequential.py\", line 308, in outputs\n    raise AttributeError(\nAttributeError: Sequential model 'sequential_92' has no defined outputs yet.\n\n--------------------------------------------------------------------------------\n1 fits failed with the following error:\nTraceback (most recent call last):\n  File \"/usr/local/lib/python3.11/dist-packages/sklearn/model_selection/_validation.py\", line 895, in _fit_and_score\n    estimator.fit(X_train, y_train, **fit_params)\n  File \"/usr/local/lib/python3.11/dist-packages/scikeras/wrappers.py\", line 1491, in fit\n    super().fit(X=X, y=y, sample_weight=sample_weight, **kwargs)\n  File \"/usr/local/lib/python3.11/dist-packages/scikeras/wrappers.py\", line 760, in fit\n    self._fit(\n  File \"/usr/local/lib/python3.11/dist-packages/scikeras/wrappers.py\", line 926, in _fit\n    self._check_model_compatibility(y)\n  File \"/usr/local/lib/python3.11/dist-packages/scikeras/wrappers.py\", line 549, in _check_model_compatibility\n    if self.n_outputs_expected_ != len(self.model_.outputs):\n                                       ^^^^^^^^^^^^^^^^^^^\n  File \"/usr/local/lib/python3.11/dist-packages/keras/src/models/sequential.py\", line 308, in outputs\n    raise AttributeError(\nAttributeError: Sequential model 'sequential_93' has no defined outputs yet.\n\n--------------------------------------------------------------------------------\n1 fits failed with the following error:\nTraceback (most recent call last):\n  File \"/usr/local/lib/python3.11/dist-packages/sklearn/model_selection/_validation.py\", line 895, in _fit_and_score\n    estimator.fit(X_train, y_train, **fit_params)\n  File \"/usr/local/lib/python3.11/dist-packages/scikeras/wrappers.py\", line 1491, in fit\n    super().fit(X=X, y=y, sample_weight=sample_weight, **kwargs)\n  File \"/usr/local/lib/python3.11/dist-packages/scikeras/wrappers.py\", line 760, in fit\n    self._fit(\n  File \"/usr/local/lib/python3.11/dist-packages/scikeras/wrappers.py\", line 926, in _fit\n    self._check_model_compatibility(y)\n  File \"/usr/local/lib/python3.11/dist-packages/scikeras/wrappers.py\", line 549, in _check_model_compatibility\n    if self.n_outputs_expected_ != len(self.model_.outputs):\n                                       ^^^^^^^^^^^^^^^^^^^\n  File \"/usr/local/lib/python3.11/dist-packages/keras/src/models/sequential.py\", line 308, in outputs\n    raise AttributeError(\nAttributeError: Sequential model 'sequential_94' has no defined outputs yet.\n\n--------------------------------------------------------------------------------\n1 fits failed with the following error:\nTraceback (most recent call last):\n  File \"/usr/local/lib/python3.11/dist-packages/sklearn/model_selection/_validation.py\", line 895, in _fit_and_score\n    estimator.fit(X_train, y_train, **fit_params)\n  File \"/usr/local/lib/python3.11/dist-packages/scikeras/wrappers.py\", line 1491, in fit\n    super().fit(X=X, y=y, sample_weight=sample_weight, **kwargs)\n  File \"/usr/local/lib/python3.11/dist-packages/scikeras/wrappers.py\", line 760, in fit\n    self._fit(\n  File \"/usr/local/lib/python3.11/dist-packages/scikeras/wrappers.py\", line 926, in _fit\n    self._check_model_compatibility(y)\n  File \"/usr/local/lib/python3.11/dist-packages/scikeras/wrappers.py\", line 549, in _check_model_compatibility\n    if self.n_outputs_expected_ != len(self.model_.outputs):\n                                       ^^^^^^^^^^^^^^^^^^^\n  File \"/usr/local/lib/python3.11/dist-packages/keras/src/models/sequential.py\", line 308, in outputs\n    raise AttributeError(\nAttributeError: Sequential model 'sequential_95' has no defined outputs yet.\n\n--------------------------------------------------------------------------------\n1 fits failed with the following error:\nTraceback (most recent call last):\n  File \"/usr/local/lib/python3.11/dist-packages/sklearn/model_selection/_validation.py\", line 895, in _fit_and_score\n    estimator.fit(X_train, y_train, **fit_params)\n  File \"/usr/local/lib/python3.11/dist-packages/scikeras/wrappers.py\", line 1491, in fit\n    super().fit(X=X, y=y, sample_weight=sample_weight, **kwargs)\n  File \"/usr/local/lib/python3.11/dist-packages/scikeras/wrappers.py\", line 760, in fit\n    self._fit(\n  File \"/usr/local/lib/python3.11/dist-packages/scikeras/wrappers.py\", line 926, in _fit\n    self._check_model_compatibility(y)\n  File \"/usr/local/lib/python3.11/dist-packages/scikeras/wrappers.py\", line 549, in _check_model_compatibility\n    if self.n_outputs_expected_ != len(self.model_.outputs):\n                                       ^^^^^^^^^^^^^^^^^^^\n  File \"/usr/local/lib/python3.11/dist-packages/keras/src/models/sequential.py\", line 308, in outputs\n    raise AttributeError(\nAttributeError: Sequential model 'sequential_96' has no defined outputs yet.\n\n--------------------------------------------------------------------------------\n1 fits failed with the following error:\nTraceback (most recent call last):\n  File \"/usr/local/lib/python3.11/dist-packages/sklearn/model_selection/_validation.py\", line 895, in _fit_and_score\n    estimator.fit(X_train, y_train, **fit_params)\n  File \"/usr/local/lib/python3.11/dist-packages/scikeras/wrappers.py\", line 1491, in fit\n    super().fit(X=X, y=y, sample_weight=sample_weight, **kwargs)\n  File \"/usr/local/lib/python3.11/dist-packages/scikeras/wrappers.py\", line 760, in fit\n    self._fit(\n  File \"/usr/local/lib/python3.11/dist-packages/scikeras/wrappers.py\", line 926, in _fit\n    self._check_model_compatibility(y)\n  File \"/usr/local/lib/python3.11/dist-packages/scikeras/wrappers.py\", line 549, in _check_model_compatibility\n    if self.n_outputs_expected_ != len(self.model_.outputs):\n                                       ^^^^^^^^^^^^^^^^^^^\n  File \"/usr/local/lib/python3.11/dist-packages/keras/src/models/sequential.py\", line 308, in outputs\n    raise AttributeError(\nAttributeError: Sequential model 'sequential_97' has no defined outputs yet.\n"
          ]
        }
      ]
    }
  ]
}